{"timestamp": "2025-05-15T23:59:48.029779", "level": "ERROR", "logger": "app.utils.verificaImagemVideo", "message": "Erro ao analisar imagem: 404 Publisher Model `projects/conteudo-autenticare/locations/us-central1/publishers/google/models/gemini-pro-vision` was not found or your project does not have access to it. Please ensure you are using a valid model version. For more information, see: https://cloud.google.com/vertex-ai/generative-ai/docs/learn/model-versions", "exception": {"type": "NotFound", "message": "404 Publisher Model `projects/conteudo-autenticare/locations/us-central1/publishers/google/models/gemini-pro-vision` was not found or your project does not have access to it. Please ensure you are using a valid model version. For more information, see: https://cloud.google.com/vertex-ai/generative-ai/docs/learn/model-versions", "traceback": "Traceback (most recent call last):\n  File \"/home/rafael/.local/lib/python3.9/site-packages/google/api_core/grpc_helpers.py\", line 76, in error_remapped_callable\n    return callable_(*args, **kwargs)\n  File \"/home/rafael/.local/lib/python3.9/site-packages/grpc/_channel.py\", line 1181, in __call__\n    return _end_unary_response_blocking(state, call, False, None)\n  File \"/home/rafael/.local/lib/python3.9/site-packages/grpc/_channel.py\", line 1006, in _end_unary_response_blocking\n    raise _InactiveRpcError(state)  # pytype: disable=not-instantiable\ngrpc._channel._InactiveRpcError: <_InactiveRpcError of RPC that terminated with:\n\tstatus = StatusCode.NOT_FOUND\n\tdetails = \"Publisher Model `projects/conteudo-autenticare/locations/us-central1/publishers/google/models/gemini-pro-vision` was not found or your project does not have access to it. Please ensure you are using a valid model version. For more information, see: https://cloud.google.com/vertex-ai/generative-ai/docs/learn/model-versions\"\n\tdebug_error_string = \"UNKNOWN:Error received from peer ipv4:172.217.30.106:443 {grpc_message:\"Publisher Model `projects/conteudo-autenticare/locations/us-central1/publishers/google/models/gemini-pro-vision` was not found or your project does not have access to it. Please ensure you are using a valid model version. For more information, see: https://cloud.google.com/vertex-ai/generative-ai/docs/learn/model-versions\", grpc_status:5}\"\n>\n\nThe above exception was the direct cause of the following exception:\n\nTraceback (most recent call last):\n  File \"/home/rafael/Desktop/projetos/yduqs_back/app/utils/verificaImagemVideo.py\", line 83, in analisar_imagem\n    response = model.generate_content([prompt, image])\n  File \"/home/rafael/.local/lib/python3.9/site-packages/vertexai/generative_models/_generative_models.py\", line 654, in generate_content\n    return self._generate_content(\n  File \"/home/rafael/.local/lib/python3.9/site-packages/vertexai/generative_models/_generative_models.py\", line 779, in _generate_content\n    gapic_response = self._prediction_client.generate_content(request=request)\n  File \"/home/rafael/.local/lib/python3.9/site-packages/google/cloud/aiplatform_v1/services/prediction_service/client.py\", line 2159, in generate_content\n    response = rpc(\n  File \"/home/rafael/.local/lib/python3.9/site-packages/google/api_core/gapic_v1/method.py\", line 131, in __call__\n    return wrapped_func(*args, **kwargs)\n  File \"/home/rafael/.local/lib/python3.9/site-packages/google/api_core/grpc_helpers.py\", line 78, in error_remapped_callable\n    raise exceptions.from_grpc_error(exc) from exc\ngoogle.api_core.exceptions.NotFound: 404 Publisher Model `projects/conteudo-autenticare/locations/us-central1/publishers/google/models/gemini-pro-vision` was not found or your project does not have access to it. Please ensure you are using a valid model version. For more information, see: https://cloud.google.com/vertex-ai/generative-ai/docs/learn/model-versions"}}
{"timestamp": "2025-05-15T23:59:52.466107", "level": "ERROR", "logger": "app.utils.verificaImagemVideo", "message": "Erro ao analisar imagem: 404 Publisher Model `projects/conteudo-autenticare/locations/us-central1/publishers/google/models/gemini-pro-vision` was not found or your project does not have access to it. Please ensure you are using a valid model version. For more information, see: https://cloud.google.com/vertex-ai/generative-ai/docs/learn/model-versions", "exception": {"type": "NotFound", "message": "404 Publisher Model `projects/conteudo-autenticare/locations/us-central1/publishers/google/models/gemini-pro-vision` was not found or your project does not have access to it. Please ensure you are using a valid model version. For more information, see: https://cloud.google.com/vertex-ai/generative-ai/docs/learn/model-versions", "traceback": "Traceback (most recent call last):\n  File \"/home/rafael/.local/lib/python3.9/site-packages/google/api_core/grpc_helpers.py\", line 76, in error_remapped_callable\n    return callable_(*args, **kwargs)\n  File \"/home/rafael/.local/lib/python3.9/site-packages/grpc/_channel.py\", line 1181, in __call__\n    return _end_unary_response_blocking(state, call, False, None)\n  File \"/home/rafael/.local/lib/python3.9/site-packages/grpc/_channel.py\", line 1006, in _end_unary_response_blocking\n    raise _InactiveRpcError(state)  # pytype: disable=not-instantiable\ngrpc._channel._InactiveRpcError: <_InactiveRpcError of RPC that terminated with:\n\tstatus = StatusCode.NOT_FOUND\n\tdetails = \"Publisher Model `projects/conteudo-autenticare/locations/us-central1/publishers/google/models/gemini-pro-vision` was not found or your project does not have access to it. Please ensure you are using a valid model version. For more information, see: https://cloud.google.com/vertex-ai/generative-ai/docs/learn/model-versions\"\n\tdebug_error_string = \"UNKNOWN:Error received from peer ipv4:142.251.135.10:443 {grpc_status:5, grpc_message:\"Publisher Model `projects/conteudo-autenticare/locations/us-central1/publishers/google/models/gemini-pro-vision` was not found or your project does not have access to it. Please ensure you are using a valid model version. For more information, see: https://cloud.google.com/vertex-ai/generative-ai/docs/learn/model-versions\"}\"\n>\n\nThe above exception was the direct cause of the following exception:\n\nTraceback (most recent call last):\n  File \"/home/rafael/Desktop/projetos/yduqs_back/app/utils/verificaImagemVideo.py\", line 83, in analisar_imagem\n    response = model.generate_content([prompt, image])\n  File \"/home/rafael/.local/lib/python3.9/site-packages/vertexai/generative_models/_generative_models.py\", line 654, in generate_content\n    return self._generate_content(\n  File \"/home/rafael/.local/lib/python3.9/site-packages/vertexai/generative_models/_generative_models.py\", line 779, in _generate_content\n    gapic_response = self._prediction_client.generate_content(request=request)\n  File \"/home/rafael/.local/lib/python3.9/site-packages/google/cloud/aiplatform_v1/services/prediction_service/client.py\", line 2159, in generate_content\n    response = rpc(\n  File \"/home/rafael/.local/lib/python3.9/site-packages/google/api_core/gapic_v1/method.py\", line 131, in __call__\n    return wrapped_func(*args, **kwargs)\n  File \"/home/rafael/.local/lib/python3.9/site-packages/google/api_core/grpc_helpers.py\", line 78, in error_remapped_callable\n    raise exceptions.from_grpc_error(exc) from exc\ngoogle.api_core.exceptions.NotFound: 404 Publisher Model `projects/conteudo-autenticare/locations/us-central1/publishers/google/models/gemini-pro-vision` was not found or your project does not have access to it. Please ensure you are using a valid model version. For more information, see: https://cloud.google.com/vertex-ai/generative-ai/docs/learn/model-versions"}}
{"timestamp": "2025-05-15T23:59:58.217459", "level": "ERROR", "logger": "app.utils.verificaImagemVideo", "message": "Erro ao analisar imagem: 404 Publisher Model `projects/conteudo-autenticare/locations/us-central1/publishers/google/models/gemini-pro-vision` was not found or your project does not have access to it. Please ensure you are using a valid model version. For more information, see: https://cloud.google.com/vertex-ai/generative-ai/docs/learn/model-versions", "exception": {"type": "NotFound", "message": "404 Publisher Model `projects/conteudo-autenticare/locations/us-central1/publishers/google/models/gemini-pro-vision` was not found or your project does not have access to it. Please ensure you are using a valid model version. For more information, see: https://cloud.google.com/vertex-ai/generative-ai/docs/learn/model-versions", "traceback": "Traceback (most recent call last):\n  File \"/home/rafael/.local/lib/python3.9/site-packages/google/api_core/grpc_helpers.py\", line 76, in error_remapped_callable\n    return callable_(*args, **kwargs)\n  File \"/home/rafael/.local/lib/python3.9/site-packages/grpc/_channel.py\", line 1181, in __call__\n    return _end_unary_response_blocking(state, call, False, None)\n  File \"/home/rafael/.local/lib/python3.9/site-packages/grpc/_channel.py\", line 1006, in _end_unary_response_blocking\n    raise _InactiveRpcError(state)  # pytype: disable=not-instantiable\ngrpc._channel._InactiveRpcError: <_InactiveRpcError of RPC that terminated with:\n\tstatus = StatusCode.NOT_FOUND\n\tdetails = \"Publisher Model `projects/conteudo-autenticare/locations/us-central1/publishers/google/models/gemini-pro-vision` was not found or your project does not have access to it. Please ensure you are using a valid model version. For more information, see: https://cloud.google.com/vertex-ai/generative-ai/docs/learn/model-versions\"\n\tdebug_error_string = \"UNKNOWN:Error received from peer ipv4:172.217.28.42:443 {grpc_status:5, grpc_message:\"Publisher Model `projects/conteudo-autenticare/locations/us-central1/publishers/google/models/gemini-pro-vision` was not found or your project does not have access to it. Please ensure you are using a valid model version. For more information, see: https://cloud.google.com/vertex-ai/generative-ai/docs/learn/model-versions\"}\"\n>\n\nThe above exception was the direct cause of the following exception:\n\nTraceback (most recent call last):\n  File \"/home/rafael/Desktop/projetos/yduqs_back/app/utils/verificaImagemVideo.py\", line 83, in analisar_imagem\n    response = model.generate_content([prompt, image])\n  File \"/home/rafael/.local/lib/python3.9/site-packages/vertexai/generative_models/_generative_models.py\", line 654, in generate_content\n    return self._generate_content(\n  File \"/home/rafael/.local/lib/python3.9/site-packages/vertexai/generative_models/_generative_models.py\", line 779, in _generate_content\n    gapic_response = self._prediction_client.generate_content(request=request)\n  File \"/home/rafael/.local/lib/python3.9/site-packages/google/cloud/aiplatform_v1/services/prediction_service/client.py\", line 2159, in generate_content\n    response = rpc(\n  File \"/home/rafael/.local/lib/python3.9/site-packages/google/api_core/gapic_v1/method.py\", line 131, in __call__\n    return wrapped_func(*args, **kwargs)\n  File \"/home/rafael/.local/lib/python3.9/site-packages/google/api_core/grpc_helpers.py\", line 78, in error_remapped_callable\n    raise exceptions.from_grpc_error(exc) from exc\ngoogle.api_core.exceptions.NotFound: 404 Publisher Model `projects/conteudo-autenticare/locations/us-central1/publishers/google/models/gemini-pro-vision` was not found or your project does not have access to it. Please ensure you are using a valid model version. For more information, see: https://cloud.google.com/vertex-ai/generative-ai/docs/learn/model-versions"}}
{"timestamp": "2025-05-16T01:00:52.426654", "level": "ERROR", "logger": "app.utils.verificaImagemVideo", "message": "Erro ao analisar imagem: module 'app.settings' has no attribute 'GEMINI_MODEL'", "exception": {"type": "AttributeError", "message": "module 'app.settings' has no attribute 'GEMINI_MODEL'", "traceback": "Traceback (most recent call last):\n  File \"/home/rafael/Desktop/projetos/yduqs_back/app/utils/verificaImagemVideo.py\", line 58, in analisar_imagem\n    model = GenerativeModel(settings.GEMINI_MODEL)\nAttributeError: module 'app.settings' has no attribute 'GEMINI_MODEL'"}}
{"timestamp": "2025-05-16T01:00:52.816790", "level": "ERROR", "logger": "app.utils.verificaImagemVideo", "message": "Erro ao analisar imagem: module 'app.settings' has no attribute 'GEMINI_MODEL'", "exception": {"type": "AttributeError", "message": "module 'app.settings' has no attribute 'GEMINI_MODEL'", "traceback": "Traceback (most recent call last):\n  File \"/home/rafael/Desktop/projetos/yduqs_back/app/utils/verificaImagemVideo.py\", line 58, in analisar_imagem\n    model = GenerativeModel(settings.GEMINI_MODEL)\nAttributeError: module 'app.settings' has no attribute 'GEMINI_MODEL'"}}
{"timestamp": "2025-05-16T01:00:53.071887", "level": "ERROR", "logger": "app.utils.verificaImagemVideo", "message": "Erro ao analisar imagem: module 'app.settings' has no attribute 'GEMINI_MODEL'", "exception": {"type": "AttributeError", "message": "module 'app.settings' has no attribute 'GEMINI_MODEL'", "traceback": "Traceback (most recent call last):\n  File \"/home/rafael/Desktop/projetos/yduqs_back/app/utils/verificaImagemVideo.py\", line 58, in analisar_imagem\n    model = GenerativeModel(settings.GEMINI_MODEL)\nAttributeError: module 'app.settings' has no attribute 'GEMINI_MODEL'"}}
{"timestamp": "2025-05-16T01:00:53.599611", "level": "ERROR", "logger": "app.utils.verificaImagemVideo", "message": "Erro ao analisar imagem: module 'app.settings' has no attribute 'GEMINI_MODEL'", "exception": {"type": "AttributeError", "message": "module 'app.settings' has no attribute 'GEMINI_MODEL'", "traceback": "Traceback (most recent call last):\n  File \"/home/rafael/Desktop/projetos/yduqs_back/app/utils/verificaImagemVideo.py\", line 58, in analisar_imagem\n    model = GenerativeModel(settings.GEMINI_MODEL)\nAttributeError: module 'app.settings' has no attribute 'GEMINI_MODEL'"}}
{"timestamp": "2025-05-16T01:00:54.017405", "level": "ERROR", "logger": "app.utils.verificaImagemVideo", "message": "Erro ao analisar imagem: module 'app.settings' has no attribute 'GEMINI_MODEL'", "exception": {"type": "AttributeError", "message": "module 'app.settings' has no attribute 'GEMINI_MODEL'", "traceback": "Traceback (most recent call last):\n  File \"/home/rafael/Desktop/projetos/yduqs_back/app/utils/verificaImagemVideo.py\", line 58, in analisar_imagem\n    model = GenerativeModel(settings.GEMINI_MODEL)\nAttributeError: module 'app.settings' has no attribute 'GEMINI_MODEL'"}}
{"timestamp": "2025-05-16T01:00:55.278371", "level": "ERROR", "logger": "app.utils.verificaImagemVideo", "message": "Erro ao analisar imagem: module 'app.settings' has no attribute 'GEMINI_MODEL'", "exception": {"type": "AttributeError", "message": "module 'app.settings' has no attribute 'GEMINI_MODEL'", "traceback": "Traceback (most recent call last):\n  File \"/home/rafael/Desktop/projetos/yduqs_back/app/utils/verificaImagemVideo.py\", line 58, in analisar_imagem\n    model = GenerativeModel(settings.GEMINI_MODEL)\nAttributeError: module 'app.settings' has no attribute 'GEMINI_MODEL'"}}
{"timestamp": "2025-05-16T01:00:56.294131", "level": "ERROR", "logger": "app.utils.verificaImagemVideo", "message": "Erro ao analisar imagem: module 'app.settings' has no attribute 'GEMINI_MODEL'", "exception": {"type": "AttributeError", "message": "module 'app.settings' has no attribute 'GEMINI_MODEL'", "traceback": "Traceback (most recent call last):\n  File \"/home/rafael/Desktop/projetos/yduqs_back/app/utils/verificaImagemVideo.py\", line 58, in analisar_imagem\n    model = GenerativeModel(settings.GEMINI_MODEL)\nAttributeError: module 'app.settings' has no attribute 'GEMINI_MODEL'"}}
{"timestamp": "2025-05-16T01:00:56.702816", "level": "ERROR", "logger": "app.utils.verificaImagemVideo", "message": "Erro ao analisar imagem: module 'app.settings' has no attribute 'GEMINI_MODEL'", "exception": {"type": "AttributeError", "message": "module 'app.settings' has no attribute 'GEMINI_MODEL'", "traceback": "Traceback (most recent call last):\n  File \"/home/rafael/Desktop/projetos/yduqs_back/app/utils/verificaImagemVideo.py\", line 58, in analisar_imagem\n    model = GenerativeModel(settings.GEMINI_MODEL)\nAttributeError: module 'app.settings' has no attribute 'GEMINI_MODEL'"}}
{"timestamp": "2025-05-16T01:00:58.025451", "level": "ERROR", "logger": "app.utils.verificaImagemVideo", "message": "Erro ao analisar imagem: module 'app.settings' has no attribute 'GEMINI_MODEL'", "exception": {"type": "AttributeError", "message": "module 'app.settings' has no attribute 'GEMINI_MODEL'", "traceback": "Traceback (most recent call last):\n  File \"/home/rafael/Desktop/projetos/yduqs_back/app/utils/verificaImagemVideo.py\", line 58, in analisar_imagem\n    model = GenerativeModel(settings.GEMINI_MODEL)\nAttributeError: module 'app.settings' has no attribute 'GEMINI_MODEL'"}}
{"timestamp": "2025-05-16T01:00:59.624820", "level": "ERROR", "logger": "app.utils.verificaImagemVideo", "message": "Erro ao analisar imagem: module 'app.settings' has no attribute 'GEMINI_MODEL'", "exception": {"type": "AttributeError", "message": "module 'app.settings' has no attribute 'GEMINI_MODEL'", "traceback": "Traceback (most recent call last):\n  File \"/home/rafael/Desktop/projetos/yduqs_back/app/utils/verificaImagemVideo.py\", line 58, in analisar_imagem\n    model = GenerativeModel(settings.GEMINI_MODEL)\nAttributeError: module 'app.settings' has no attribute 'GEMINI_MODEL'"}}
{"timestamp": "2025-05-16T01:07:22.366468", "level": "ERROR", "logger": "app.utils.verificaImagemVideo", "message": "Erro ao analisar imagem: object GenerationResponse can't be used in 'await' expression", "exception": {"type": "TypeError", "message": "object GenerationResponse can't be used in 'await' expression", "traceback": "Traceback (most recent call last):\n  File \"/home/rafael/Desktop/projetos/yduqs_back/app/utils/verificaImagemVideo.py\", line 84, in analisar_imagem\n    response = await model.generate_content([prompt, image])\nTypeError: object GenerationResponse can't be used in 'await' expression"}}
{"timestamp": "2025-05-16T01:07:25.308202", "level": "ERROR", "logger": "app.utils.verificaImagemVideo", "message": "Erro ao analisar imagem: object GenerationResponse can't be used in 'await' expression", "exception": {"type": "TypeError", "message": "object GenerationResponse can't be used in 'await' expression", "traceback": "Traceback (most recent call last):\n  File \"/home/rafael/Desktop/projetos/yduqs_back/app/utils/verificaImagemVideo.py\", line 84, in analisar_imagem\n    response = await model.generate_content([prompt, image])\nTypeError: object GenerationResponse can't be used in 'await' expression"}}
{"timestamp": "2025-05-16T01:07:28.332750", "level": "ERROR", "logger": "app.utils.verificaImagemVideo", "message": "Erro ao analisar imagem: object GenerationResponse can't be used in 'await' expression", "exception": {"type": "TypeError", "message": "object GenerationResponse can't be used in 'await' expression", "traceback": "Traceback (most recent call last):\n  File \"/home/rafael/Desktop/projetos/yduqs_back/app/utils/verificaImagemVideo.py\", line 84, in analisar_imagem\n    response = await model.generate_content([prompt, image])\nTypeError: object GenerationResponse can't be used in 'await' expression"}}
{"timestamp": "2025-05-16T01:07:31.683647", "level": "ERROR", "logger": "app.utils.verificaImagemVideo", "message": "Erro ao analisar imagem: object GenerationResponse can't be used in 'await' expression", "exception": {"type": "TypeError", "message": "object GenerationResponse can't be used in 'await' expression", "traceback": "Traceback (most recent call last):\n  File \"/home/rafael/Desktop/projetos/yduqs_back/app/utils/verificaImagemVideo.py\", line 84, in analisar_imagem\n    response = await model.generate_content([prompt, image])\nTypeError: object GenerationResponse can't be used in 'await' expression"}}
{"timestamp": "2025-05-16T01:07:35.008544", "level": "ERROR", "logger": "app.utils.verificaImagemVideo", "message": "Erro ao analisar imagem: object GenerationResponse can't be used in 'await' expression", "exception": {"type": "TypeError", "message": "object GenerationResponse can't be used in 'await' expression", "traceback": "Traceback (most recent call last):\n  File \"/home/rafael/Desktop/projetos/yduqs_back/app/utils/verificaImagemVideo.py\", line 84, in analisar_imagem\n    response = await model.generate_content([prompt, image])\nTypeError: object GenerationResponse can't be used in 'await' expression"}}
{"timestamp": "2025-05-16T01:07:37.592748", "level": "ERROR", "logger": "app.utils.verificaImagemVideo", "message": "Erro ao analisar imagem: object GenerationResponse can't be used in 'await' expression", "exception": {"type": "TypeError", "message": "object GenerationResponse can't be used in 'await' expression", "traceback": "Traceback (most recent call last):\n  File \"/home/rafael/Desktop/projetos/yduqs_back/app/utils/verificaImagemVideo.py\", line 84, in analisar_imagem\n    response = await model.generate_content([prompt, image])\nTypeError: object GenerationResponse can't be used in 'await' expression"}}
{"timestamp": "2025-05-16T01:07:40.996505", "level": "ERROR", "logger": "app.utils.verificaImagemVideo", "message": "Erro ao analisar imagem: object GenerationResponse can't be used in 'await' expression", "exception": {"type": "TypeError", "message": "object GenerationResponse can't be used in 'await' expression", "traceback": "Traceback (most recent call last):\n  File \"/home/rafael/Desktop/projetos/yduqs_back/app/utils/verificaImagemVideo.py\", line 84, in analisar_imagem\n    response = await model.generate_content([prompt, image])\nTypeError: object GenerationResponse can't be used in 'await' expression"}}
{"timestamp": "2025-05-16T01:07:43.704941", "level": "ERROR", "logger": "app.utils.verificaImagemVideo", "message": "Erro ao analisar imagem: object GenerationResponse can't be used in 'await' expression", "exception": {"type": "TypeError", "message": "object GenerationResponse can't be used in 'await' expression", "traceback": "Traceback (most recent call last):\n  File \"/home/rafael/Desktop/projetos/yduqs_back/app/utils/verificaImagemVideo.py\", line 84, in analisar_imagem\n    response = await model.generate_content([prompt, image])\nTypeError: object GenerationResponse can't be used in 'await' expression"}}
{"timestamp": "2025-05-16T01:07:46.800439", "level": "ERROR", "logger": "app.utils.verificaImagemVideo", "message": "Erro ao analisar imagem: object GenerationResponse can't be used in 'await' expression", "exception": {"type": "TypeError", "message": "object GenerationResponse can't be used in 'await' expression", "traceback": "Traceback (most recent call last):\n  File \"/home/rafael/Desktop/projetos/yduqs_back/app/utils/verificaImagemVideo.py\", line 84, in analisar_imagem\n    response = await model.generate_content([prompt, image])\nTypeError: object GenerationResponse can't be used in 'await' expression"}}
{"timestamp": "2025-05-16T01:07:49.911529", "level": "ERROR", "logger": "app.utils.verificaImagemVideo", "message": "Erro ao analisar imagem: object GenerationResponse can't be used in 'await' expression", "exception": {"type": "TypeError", "message": "object GenerationResponse can't be used in 'await' expression", "traceback": "Traceback (most recent call last):\n  File \"/home/rafael/Desktop/projetos/yduqs_back/app/utils/verificaImagemVideo.py\", line 84, in analisar_imagem\n    response = await model.generate_content([prompt, image])\nTypeError: object GenerationResponse can't be used in 'await' expression"}}
{"timestamp": "2025-05-16T01:07:53.116246", "level": "ERROR", "logger": "app.utils.verificaImagemVideo", "message": "Erro ao analisar imagem: object GenerationResponse can't be used in 'await' expression", "exception": {"type": "TypeError", "message": "object GenerationResponse can't be used in 'await' expression", "traceback": "Traceback (most recent call last):\n  File \"/home/rafael/Desktop/projetos/yduqs_back/app/utils/verificaImagemVideo.py\", line 84, in analisar_imagem\n    response = await model.generate_content([prompt, image])\nTypeError: object GenerationResponse can't be used in 'await' expression"}}
{"timestamp": "2025-05-16T01:07:56.033734", "level": "ERROR", "logger": "app.utils.verificaImagemVideo", "message": "Erro ao analisar imagem: object GenerationResponse can't be used in 'await' expression", "exception": {"type": "TypeError", "message": "object GenerationResponse can't be used in 'await' expression", "traceback": "Traceback (most recent call last):\n  File \"/home/rafael/Desktop/projetos/yduqs_back/app/utils/verificaImagemVideo.py\", line 84, in analisar_imagem\n    response = await model.generate_content([prompt, image])\nTypeError: object GenerationResponse can't be used in 'await' expression"}}
{"timestamp": "2025-05-16T01:08:00.139268", "level": "ERROR", "logger": "app.utils.verificaImagemVideo", "message": "Erro ao analisar imagem: object GenerationResponse can't be used in 'await' expression", "exception": {"type": "TypeError", "message": "object GenerationResponse can't be used in 'await' expression", "traceback": "Traceback (most recent call last):\n  File \"/home/rafael/Desktop/projetos/yduqs_back/app/utils/verificaImagemVideo.py\", line 84, in analisar_imagem\n    response = await model.generate_content([prompt, image])\nTypeError: object GenerationResponse can't be used in 'await' expression"}}
{"timestamp": "2025-05-16T01:58:25.778203", "level": "ERROR", "logger": "app.utils.verificaImagemVideo", "message": "Erro ao analisar imagem: 404 Publisher Model `projects/conteudo-autenticare/locations/us-central1/publishers/google/models/gemini-pro-vision` was not found or your project does not have access to it. Please ensure you are using a valid model version. For more information, see: https://cloud.google.com/vertex-ai/generative-ai/docs/learn/model-versions", "exception": {"type": "NotFound", "message": "404 Publisher Model `projects/conteudo-autenticare/locations/us-central1/publishers/google/models/gemini-pro-vision` was not found or your project does not have access to it. Please ensure you are using a valid model version. For more information, see: https://cloud.google.com/vertex-ai/generative-ai/docs/learn/model-versions", "traceback": "Traceback (most recent call last):\n  File \"/home/rafael/.local/lib/python3.9/site-packages/google/api_core/grpc_helpers.py\", line 76, in error_remapped_callable\n    return callable_(*args, **kwargs)\n  File \"/home/rafael/.local/lib/python3.9/site-packages/grpc/_channel.py\", line 1181, in __call__\n    return _end_unary_response_blocking(state, call, False, None)\n  File \"/home/rafael/.local/lib/python3.9/site-packages/grpc/_channel.py\", line 1006, in _end_unary_response_blocking\n    raise _InactiveRpcError(state)  # pytype: disable=not-instantiable\ngrpc._channel._InactiveRpcError: <_InactiveRpcError of RPC that terminated with:\n\tstatus = StatusCode.NOT_FOUND\n\tdetails = \"Publisher Model `projects/conteudo-autenticare/locations/us-central1/publishers/google/models/gemini-pro-vision` was not found or your project does not have access to it. Please ensure you are using a valid model version. For more information, see: https://cloud.google.com/vertex-ai/generative-ai/docs/learn/model-versions\"\n\tdebug_error_string = \"UNKNOWN:Error received from peer ipv4:172.217.28.42:443 {grpc_status:5, grpc_message:\"Publisher Model `projects/conteudo-autenticare/locations/us-central1/publishers/google/models/gemini-pro-vision` was not found or your project does not have access to it. Please ensure you are using a valid model version. For more information, see: https://cloud.google.com/vertex-ai/generative-ai/docs/learn/model-versions\"}\"\n>\n\nThe above exception was the direct cause of the following exception:\n\nTraceback (most recent call last):\n  File \"/home/rafael/Desktop/projetos/yduqs_back/app/utils/verificaImagemVideo.py\", line 83, in analisar_imagem\n    response = model.generate_content([prompt, image])\n  File \"/home/rafael/.local/lib/python3.9/site-packages/vertexai/generative_models/_generative_models.py\", line 654, in generate_content\n    return self._generate_content(\n  File \"/home/rafael/.local/lib/python3.9/site-packages/vertexai/generative_models/_generative_models.py\", line 779, in _generate_content\n    gapic_response = self._prediction_client.generate_content(request=request)\n  File \"/home/rafael/.local/lib/python3.9/site-packages/google/cloud/aiplatform_v1/services/prediction_service/client.py\", line 2159, in generate_content\n    response = rpc(\n  File \"/home/rafael/.local/lib/python3.9/site-packages/google/api_core/gapic_v1/method.py\", line 131, in __call__\n    return wrapped_func(*args, **kwargs)\n  File \"/home/rafael/.local/lib/python3.9/site-packages/google/api_core/grpc_helpers.py\", line 78, in error_remapped_callable\n    raise exceptions.from_grpc_error(exc) from exc\ngoogle.api_core.exceptions.NotFound: 404 Publisher Model `projects/conteudo-autenticare/locations/us-central1/publishers/google/models/gemini-pro-vision` was not found or your project does not have access to it. Please ensure you are using a valid model version. For more information, see: https://cloud.google.com/vertex-ai/generative-ai/docs/learn/model-versions"}}
{"timestamp": "2025-05-16T01:58:29.080441", "level": "ERROR", "logger": "app.utils.verificaImagemVideo", "message": "Erro ao analisar imagem: 404 Publisher Model `projects/conteudo-autenticare/locations/us-central1/publishers/google/models/gemini-pro-vision` was not found or your project does not have access to it. Please ensure you are using a valid model version. For more information, see: https://cloud.google.com/vertex-ai/generative-ai/docs/learn/model-versions", "exception": {"type": "NotFound", "message": "404 Publisher Model `projects/conteudo-autenticare/locations/us-central1/publishers/google/models/gemini-pro-vision` was not found or your project does not have access to it. Please ensure you are using a valid model version. For more information, see: https://cloud.google.com/vertex-ai/generative-ai/docs/learn/model-versions", "traceback": "Traceback (most recent call last):\n  File \"/home/rafael/.local/lib/python3.9/site-packages/google/api_core/grpc_helpers.py\", line 76, in error_remapped_callable\n    return callable_(*args, **kwargs)\n  File \"/home/rafael/.local/lib/python3.9/site-packages/grpc/_channel.py\", line 1181, in __call__\n    return _end_unary_response_blocking(state, call, False, None)\n  File \"/home/rafael/.local/lib/python3.9/site-packages/grpc/_channel.py\", line 1006, in _end_unary_response_blocking\n    raise _InactiveRpcError(state)  # pytype: disable=not-instantiable\ngrpc._channel._InactiveRpcError: <_InactiveRpcError of RPC that terminated with:\n\tstatus = StatusCode.NOT_FOUND\n\tdetails = \"Publisher Model `projects/conteudo-autenticare/locations/us-central1/publishers/google/models/gemini-pro-vision` was not found or your project does not have access to it. Please ensure you are using a valid model version. For more information, see: https://cloud.google.com/vertex-ai/generative-ai/docs/learn/model-versions\"\n\tdebug_error_string = \"UNKNOWN:Error received from peer ipv4:172.217.29.202:443 {grpc_message:\"Publisher Model `projects/conteudo-autenticare/locations/us-central1/publishers/google/models/gemini-pro-vision` was not found or your project does not have access to it. Please ensure you are using a valid model version. For more information, see: https://cloud.google.com/vertex-ai/generative-ai/docs/learn/model-versions\", grpc_status:5}\"\n>\n\nThe above exception was the direct cause of the following exception:\n\nTraceback (most recent call last):\n  File \"/home/rafael/Desktop/projetos/yduqs_back/app/utils/verificaImagemVideo.py\", line 83, in analisar_imagem\n    response = model.generate_content([prompt, image])\n  File \"/home/rafael/.local/lib/python3.9/site-packages/vertexai/generative_models/_generative_models.py\", line 654, in generate_content\n    return self._generate_content(\n  File \"/home/rafael/.local/lib/python3.9/site-packages/vertexai/generative_models/_generative_models.py\", line 779, in _generate_content\n    gapic_response = self._prediction_client.generate_content(request=request)\n  File \"/home/rafael/.local/lib/python3.9/site-packages/google/cloud/aiplatform_v1/services/prediction_service/client.py\", line 2159, in generate_content\n    response = rpc(\n  File \"/home/rafael/.local/lib/python3.9/site-packages/google/api_core/gapic_v1/method.py\", line 131, in __call__\n    return wrapped_func(*args, **kwargs)\n  File \"/home/rafael/.local/lib/python3.9/site-packages/google/api_core/grpc_helpers.py\", line 78, in error_remapped_callable\n    raise exceptions.from_grpc_error(exc) from exc\ngoogle.api_core.exceptions.NotFound: 404 Publisher Model `projects/conteudo-autenticare/locations/us-central1/publishers/google/models/gemini-pro-vision` was not found or your project does not have access to it. Please ensure you are using a valid model version. For more information, see: https://cloud.google.com/vertex-ai/generative-ai/docs/learn/model-versions"}}
{"timestamp": "2025-05-16T01:58:31.784786", "level": "ERROR", "logger": "app.utils.verificaImagemVideo", "message": "Erro ao analisar imagem: 404 Publisher Model `projects/conteudo-autenticare/locations/us-central1/publishers/google/models/gemini-pro-vision` was not found or your project does not have access to it. Please ensure you are using a valid model version. For more information, see: https://cloud.google.com/vertex-ai/generative-ai/docs/learn/model-versions", "exception": {"type": "NotFound", "message": "404 Publisher Model `projects/conteudo-autenticare/locations/us-central1/publishers/google/models/gemini-pro-vision` was not found or your project does not have access to it. Please ensure you are using a valid model version. For more information, see: https://cloud.google.com/vertex-ai/generative-ai/docs/learn/model-versions", "traceback": "Traceback (most recent call last):\n  File \"/home/rafael/.local/lib/python3.9/site-packages/google/api_core/grpc_helpers.py\", line 76, in error_remapped_callable\n    return callable_(*args, **kwargs)\n  File \"/home/rafael/.local/lib/python3.9/site-packages/grpc/_channel.py\", line 1181, in __call__\n    return _end_unary_response_blocking(state, call, False, None)\n  File \"/home/rafael/.local/lib/python3.9/site-packages/grpc/_channel.py\", line 1006, in _end_unary_response_blocking\n    raise _InactiveRpcError(state)  # pytype: disable=not-instantiable\ngrpc._channel._InactiveRpcError: <_InactiveRpcError of RPC that terminated with:\n\tstatus = StatusCode.NOT_FOUND\n\tdetails = \"Publisher Model `projects/conteudo-autenticare/locations/us-central1/publishers/google/models/gemini-pro-vision` was not found or your project does not have access to it. Please ensure you are using a valid model version. For more information, see: https://cloud.google.com/vertex-ai/generative-ai/docs/learn/model-versions\"\n\tdebug_error_string = \"UNKNOWN:Error received from peer ipv4:172.217.29.74:443 {grpc_status:5, grpc_message:\"Publisher Model `projects/conteudo-autenticare/locations/us-central1/publishers/google/models/gemini-pro-vision` was not found or your project does not have access to it. Please ensure you are using a valid model version. For more information, see: https://cloud.google.com/vertex-ai/generative-ai/docs/learn/model-versions\"}\"\n>\n\nThe above exception was the direct cause of the following exception:\n\nTraceback (most recent call last):\n  File \"/home/rafael/Desktop/projetos/yduqs_back/app/utils/verificaImagemVideo.py\", line 83, in analisar_imagem\n    response = model.generate_content([prompt, image])\n  File \"/home/rafael/.local/lib/python3.9/site-packages/vertexai/generative_models/_generative_models.py\", line 654, in generate_content\n    return self._generate_content(\n  File \"/home/rafael/.local/lib/python3.9/site-packages/vertexai/generative_models/_generative_models.py\", line 779, in _generate_content\n    gapic_response = self._prediction_client.generate_content(request=request)\n  File \"/home/rafael/.local/lib/python3.9/site-packages/google/cloud/aiplatform_v1/services/prediction_service/client.py\", line 2159, in generate_content\n    response = rpc(\n  File \"/home/rafael/.local/lib/python3.9/site-packages/google/api_core/gapic_v1/method.py\", line 131, in __call__\n    return wrapped_func(*args, **kwargs)\n  File \"/home/rafael/.local/lib/python3.9/site-packages/google/api_core/grpc_helpers.py\", line 78, in error_remapped_callable\n    raise exceptions.from_grpc_error(exc) from exc\ngoogle.api_core.exceptions.NotFound: 404 Publisher Model `projects/conteudo-autenticare/locations/us-central1/publishers/google/models/gemini-pro-vision` was not found or your project does not have access to it. Please ensure you are using a valid model version. For more information, see: https://cloud.google.com/vertex-ai/generative-ai/docs/learn/model-versions"}}
{"timestamp": "2025-05-16T01:58:34.324448", "level": "ERROR", "logger": "app.utils.verificaImagemVideo", "message": "Erro ao analisar imagem: 404 Publisher Model `projects/conteudo-autenticare/locations/us-central1/publishers/google/models/gemini-pro-vision` was not found or your project does not have access to it. Please ensure you are using a valid model version. For more information, see: https://cloud.google.com/vertex-ai/generative-ai/docs/learn/model-versions", "exception": {"type": "NotFound", "message": "404 Publisher Model `projects/conteudo-autenticare/locations/us-central1/publishers/google/models/gemini-pro-vision` was not found or your project does not have access to it. Please ensure you are using a valid model version. For more information, see: https://cloud.google.com/vertex-ai/generative-ai/docs/learn/model-versions", "traceback": "Traceback (most recent call last):\n  File \"/home/rafael/.local/lib/python3.9/site-packages/google/api_core/grpc_helpers.py\", line 76, in error_remapped_callable\n    return callable_(*args, **kwargs)\n  File \"/home/rafael/.local/lib/python3.9/site-packages/grpc/_channel.py\", line 1181, in __call__\n    return _end_unary_response_blocking(state, call, False, None)\n  File \"/home/rafael/.local/lib/python3.9/site-packages/grpc/_channel.py\", line 1006, in _end_unary_response_blocking\n    raise _InactiveRpcError(state)  # pytype: disable=not-instantiable\ngrpc._channel._InactiveRpcError: <_InactiveRpcError of RPC that terminated with:\n\tstatus = StatusCode.NOT_FOUND\n\tdetails = \"Publisher Model `projects/conteudo-autenticare/locations/us-central1/publishers/google/models/gemini-pro-vision` was not found or your project does not have access to it. Please ensure you are using a valid model version. For more information, see: https://cloud.google.com/vertex-ai/generative-ai/docs/learn/model-versions\"\n\tdebug_error_string = \"UNKNOWN:Error received from peer ipv4:172.217.172.138:443 {grpc_status:5, grpc_message:\"Publisher Model `projects/conteudo-autenticare/locations/us-central1/publishers/google/models/gemini-pro-vision` was not found or your project does not have access to it. Please ensure you are using a valid model version. For more information, see: https://cloud.google.com/vertex-ai/generative-ai/docs/learn/model-versions\"}\"\n>\n\nThe above exception was the direct cause of the following exception:\n\nTraceback (most recent call last):\n  File \"/home/rafael/Desktop/projetos/yduqs_back/app/utils/verificaImagemVideo.py\", line 83, in analisar_imagem\n    response = model.generate_content([prompt, image])\n  File \"/home/rafael/.local/lib/python3.9/site-packages/vertexai/generative_models/_generative_models.py\", line 654, in generate_content\n    return self._generate_content(\n  File \"/home/rafael/.local/lib/python3.9/site-packages/vertexai/generative_models/_generative_models.py\", line 779, in _generate_content\n    gapic_response = self._prediction_client.generate_content(request=request)\n  File \"/home/rafael/.local/lib/python3.9/site-packages/google/cloud/aiplatform_v1/services/prediction_service/client.py\", line 2159, in generate_content\n    response = rpc(\n  File \"/home/rafael/.local/lib/python3.9/site-packages/google/api_core/gapic_v1/method.py\", line 131, in __call__\n    return wrapped_func(*args, **kwargs)\n  File \"/home/rafael/.local/lib/python3.9/site-packages/google/api_core/grpc_helpers.py\", line 78, in error_remapped_callable\n    raise exceptions.from_grpc_error(exc) from exc\ngoogle.api_core.exceptions.NotFound: 404 Publisher Model `projects/conteudo-autenticare/locations/us-central1/publishers/google/models/gemini-pro-vision` was not found or your project does not have access to it. Please ensure you are using a valid model version. For more information, see: https://cloud.google.com/vertex-ai/generative-ai/docs/learn/model-versions"}}
{"timestamp": "2025-05-16T01:58:38.116655", "level": "ERROR", "logger": "app.utils.verificaImagemVideo", "message": "Erro ao analisar imagem: 404 Publisher Model `projects/conteudo-autenticare/locations/us-central1/publishers/google/models/gemini-pro-vision` was not found or your project does not have access to it. Please ensure you are using a valid model version. For more information, see: https://cloud.google.com/vertex-ai/generative-ai/docs/learn/model-versions", "exception": {"type": "NotFound", "message": "404 Publisher Model `projects/conteudo-autenticare/locations/us-central1/publishers/google/models/gemini-pro-vision` was not found or your project does not have access to it. Please ensure you are using a valid model version. For more information, see: https://cloud.google.com/vertex-ai/generative-ai/docs/learn/model-versions", "traceback": "Traceback (most recent call last):\n  File \"/home/rafael/.local/lib/python3.9/site-packages/google/api_core/grpc_helpers.py\", line 76, in error_remapped_callable\n    return callable_(*args, **kwargs)\n  File \"/home/rafael/.local/lib/python3.9/site-packages/grpc/_channel.py\", line 1181, in __call__\n    return _end_unary_response_blocking(state, call, False, None)\n  File \"/home/rafael/.local/lib/python3.9/site-packages/grpc/_channel.py\", line 1006, in _end_unary_response_blocking\n    raise _InactiveRpcError(state)  # pytype: disable=not-instantiable\ngrpc._channel._InactiveRpcError: <_InactiveRpcError of RPC that terminated with:\n\tstatus = StatusCode.NOT_FOUND\n\tdetails = \"Publisher Model `projects/conteudo-autenticare/locations/us-central1/publishers/google/models/gemini-pro-vision` was not found or your project does not have access to it. Please ensure you are using a valid model version. For more information, see: https://cloud.google.com/vertex-ai/generative-ai/docs/learn/model-versions\"\n\tdebug_error_string = \"UNKNOWN:Error received from peer ipv4:172.217.30.106:443 {grpc_message:\"Publisher Model `projects/conteudo-autenticare/locations/us-central1/publishers/google/models/gemini-pro-vision` was not found or your project does not have access to it. Please ensure you are using a valid model version. For more information, see: https://cloud.google.com/vertex-ai/generative-ai/docs/learn/model-versions\", grpc_status:5}\"\n>\n\nThe above exception was the direct cause of the following exception:\n\nTraceback (most recent call last):\n  File \"/home/rafael/Desktop/projetos/yduqs_back/app/utils/verificaImagemVideo.py\", line 83, in analisar_imagem\n    response = model.generate_content([prompt, image])\n  File \"/home/rafael/.local/lib/python3.9/site-packages/vertexai/generative_models/_generative_models.py\", line 654, in generate_content\n    return self._generate_content(\n  File \"/home/rafael/.local/lib/python3.9/site-packages/vertexai/generative_models/_generative_models.py\", line 779, in _generate_content\n    gapic_response = self._prediction_client.generate_content(request=request)\n  File \"/home/rafael/.local/lib/python3.9/site-packages/google/cloud/aiplatform_v1/services/prediction_service/client.py\", line 2159, in generate_content\n    response = rpc(\n  File \"/home/rafael/.local/lib/python3.9/site-packages/google/api_core/gapic_v1/method.py\", line 131, in __call__\n    return wrapped_func(*args, **kwargs)\n  File \"/home/rafael/.local/lib/python3.9/site-packages/google/api_core/grpc_helpers.py\", line 78, in error_remapped_callable\n    raise exceptions.from_grpc_error(exc) from exc\ngoogle.api_core.exceptions.NotFound: 404 Publisher Model `projects/conteudo-autenticare/locations/us-central1/publishers/google/models/gemini-pro-vision` was not found or your project does not have access to it. Please ensure you are using a valid model version. For more information, see: https://cloud.google.com/vertex-ai/generative-ai/docs/learn/model-versions"}}
{"timestamp": "2025-05-16T01:58:42.274820", "level": "ERROR", "logger": "app.utils.verificaImagemVideo", "message": "Erro ao analisar imagem: 404 Publisher Model `projects/conteudo-autenticare/locations/us-central1/publishers/google/models/gemini-pro-vision` was not found or your project does not have access to it. Please ensure you are using a valid model version. For more information, see: https://cloud.google.com/vertex-ai/generative-ai/docs/learn/model-versions", "exception": {"type": "NotFound", "message": "404 Publisher Model `projects/conteudo-autenticare/locations/us-central1/publishers/google/models/gemini-pro-vision` was not found or your project does not have access to it. Please ensure you are using a valid model version. For more information, see: https://cloud.google.com/vertex-ai/generative-ai/docs/learn/model-versions", "traceback": "Traceback (most recent call last):\n  File \"/home/rafael/.local/lib/python3.9/site-packages/google/api_core/grpc_helpers.py\", line 76, in error_remapped_callable\n    return callable_(*args, **kwargs)\n  File \"/home/rafael/.local/lib/python3.9/site-packages/grpc/_channel.py\", line 1181, in __call__\n    return _end_unary_response_blocking(state, call, False, None)\n  File \"/home/rafael/.local/lib/python3.9/site-packages/grpc/_channel.py\", line 1006, in _end_unary_response_blocking\n    raise _InactiveRpcError(state)  # pytype: disable=not-instantiable\ngrpc._channel._InactiveRpcError: <_InactiveRpcError of RPC that terminated with:\n\tstatus = StatusCode.NOT_FOUND\n\tdetails = \"Publisher Model `projects/conteudo-autenticare/locations/us-central1/publishers/google/models/gemini-pro-vision` was not found or your project does not have access to it. Please ensure you are using a valid model version. For more information, see: https://cloud.google.com/vertex-ai/generative-ai/docs/learn/model-versions\"\n\tdebug_error_string = \"UNKNOWN:Error received from peer ipv4:172.217.172.42:443 {grpc_status:5, grpc_message:\"Publisher Model `projects/conteudo-autenticare/locations/us-central1/publishers/google/models/gemini-pro-vision` was not found or your project does not have access to it. Please ensure you are using a valid model version. For more information, see: https://cloud.google.com/vertex-ai/generative-ai/docs/learn/model-versions\"}\"\n>\n\nThe above exception was the direct cause of the following exception:\n\nTraceback (most recent call last):\n  File \"/home/rafael/Desktop/projetos/yduqs_back/app/utils/verificaImagemVideo.py\", line 83, in analisar_imagem\n    response = model.generate_content([prompt, image])\n  File \"/home/rafael/.local/lib/python3.9/site-packages/vertexai/generative_models/_generative_models.py\", line 654, in generate_content\n    return self._generate_content(\n  File \"/home/rafael/.local/lib/python3.9/site-packages/vertexai/generative_models/_generative_models.py\", line 779, in _generate_content\n    gapic_response = self._prediction_client.generate_content(request=request)\n  File \"/home/rafael/.local/lib/python3.9/site-packages/google/cloud/aiplatform_v1/services/prediction_service/client.py\", line 2159, in generate_content\n    response = rpc(\n  File \"/home/rafael/.local/lib/python3.9/site-packages/google/api_core/gapic_v1/method.py\", line 131, in __call__\n    return wrapped_func(*args, **kwargs)\n  File \"/home/rafael/.local/lib/python3.9/site-packages/google/api_core/grpc_helpers.py\", line 78, in error_remapped_callable\n    raise exceptions.from_grpc_error(exc) from exc\ngoogle.api_core.exceptions.NotFound: 404 Publisher Model `projects/conteudo-autenticare/locations/us-central1/publishers/google/models/gemini-pro-vision` was not found or your project does not have access to it. Please ensure you are using a valid model version. For more information, see: https://cloud.google.com/vertex-ai/generative-ai/docs/learn/model-versions"}}
{"timestamp": "2025-05-16T01:58:44.762549", "level": "ERROR", "logger": "app.utils.verificaImagemVideo", "message": "Erro ao analisar imagem: 404 Publisher Model `projects/conteudo-autenticare/locations/us-central1/publishers/google/models/gemini-pro-vision` was not found or your project does not have access to it. Please ensure you are using a valid model version. For more information, see: https://cloud.google.com/vertex-ai/generative-ai/docs/learn/model-versions", "exception": {"type": "NotFound", "message": "404 Publisher Model `projects/conteudo-autenticare/locations/us-central1/publishers/google/models/gemini-pro-vision` was not found or your project does not have access to it. Please ensure you are using a valid model version. For more information, see: https://cloud.google.com/vertex-ai/generative-ai/docs/learn/model-versions", "traceback": "Traceback (most recent call last):\n  File \"/home/rafael/.local/lib/python3.9/site-packages/google/api_core/grpc_helpers.py\", line 76, in error_remapped_callable\n    return callable_(*args, **kwargs)\n  File \"/home/rafael/.local/lib/python3.9/site-packages/grpc/_channel.py\", line 1181, in __call__\n    return _end_unary_response_blocking(state, call, False, None)\n  File \"/home/rafael/.local/lib/python3.9/site-packages/grpc/_channel.py\", line 1006, in _end_unary_response_blocking\n    raise _InactiveRpcError(state)  # pytype: disable=not-instantiable\ngrpc._channel._InactiveRpcError: <_InactiveRpcError of RPC that terminated with:\n\tstatus = StatusCode.NOT_FOUND\n\tdetails = \"Publisher Model `projects/conteudo-autenticare/locations/us-central1/publishers/google/models/gemini-pro-vision` was not found or your project does not have access to it. Please ensure you are using a valid model version. For more information, see: https://cloud.google.com/vertex-ai/generative-ai/docs/learn/model-versions\"\n\tdebug_error_string = \"UNKNOWN:Error received from peer ipv4:172.217.30.10:443 {grpc_status:5, grpc_message:\"Publisher Model `projects/conteudo-autenticare/locations/us-central1/publishers/google/models/gemini-pro-vision` was not found or your project does not have access to it. Please ensure you are using a valid model version. For more information, see: https://cloud.google.com/vertex-ai/generative-ai/docs/learn/model-versions\"}\"\n>\n\nThe above exception was the direct cause of the following exception:\n\nTraceback (most recent call last):\n  File \"/home/rafael/Desktop/projetos/yduqs_back/app/utils/verificaImagemVideo.py\", line 83, in analisar_imagem\n    response = model.generate_content([prompt, image])\n  File \"/home/rafael/.local/lib/python3.9/site-packages/vertexai/generative_models/_generative_models.py\", line 654, in generate_content\n    return self._generate_content(\n  File \"/home/rafael/.local/lib/python3.9/site-packages/vertexai/generative_models/_generative_models.py\", line 779, in _generate_content\n    gapic_response = self._prediction_client.generate_content(request=request)\n  File \"/home/rafael/.local/lib/python3.9/site-packages/google/cloud/aiplatform_v1/services/prediction_service/client.py\", line 2159, in generate_content\n    response = rpc(\n  File \"/home/rafael/.local/lib/python3.9/site-packages/google/api_core/gapic_v1/method.py\", line 131, in __call__\n    return wrapped_func(*args, **kwargs)\n  File \"/home/rafael/.local/lib/python3.9/site-packages/google/api_core/grpc_helpers.py\", line 78, in error_remapped_callable\n    raise exceptions.from_grpc_error(exc) from exc\ngoogle.api_core.exceptions.NotFound: 404 Publisher Model `projects/conteudo-autenticare/locations/us-central1/publishers/google/models/gemini-pro-vision` was not found or your project does not have access to it. Please ensure you are using a valid model version. For more information, see: https://cloud.google.com/vertex-ai/generative-ai/docs/learn/model-versions"}}
{"timestamp": "2025-05-16T02:02:12.009139", "level": "ERROR", "logger": "app.utils.verificaImagemVideo", "message": "Erro ao analisar imagem: 404 Publisher Model `projects/conteudo-autenticare/locations/us-central1/publishers/google/models/gemini-pro-vision` was not found or your project does not have access to it. Please ensure you are using a valid model version. For more information, see: https://cloud.google.com/vertex-ai/generative-ai/docs/learn/model-versions", "exception": {"type": "NotFound", "message": "404 Publisher Model `projects/conteudo-autenticare/locations/us-central1/publishers/google/models/gemini-pro-vision` was not found or your project does not have access to it. Please ensure you are using a valid model version. For more information, see: https://cloud.google.com/vertex-ai/generative-ai/docs/learn/model-versions", "traceback": "Traceback (most recent call last):\n  File \"/home/rafael/.local/lib/python3.9/site-packages/google/api_core/grpc_helpers.py\", line 76, in error_remapped_callable\n    return callable_(*args, **kwargs)\n  File \"/home/rafael/.local/lib/python3.9/site-packages/grpc/_channel.py\", line 1181, in __call__\n    return _end_unary_response_blocking(state, call, False, None)\n  File \"/home/rafael/.local/lib/python3.9/site-packages/grpc/_channel.py\", line 1006, in _end_unary_response_blocking\n    raise _InactiveRpcError(state)  # pytype: disable=not-instantiable\ngrpc._channel._InactiveRpcError: <_InactiveRpcError of RPC that terminated with:\n\tstatus = StatusCode.NOT_FOUND\n\tdetails = \"Publisher Model `projects/conteudo-autenticare/locations/us-central1/publishers/google/models/gemini-pro-vision` was not found or your project does not have access to it. Please ensure you are using a valid model version. For more information, see: https://cloud.google.com/vertex-ai/generative-ai/docs/learn/model-versions\"\n\tdebug_error_string = \"UNKNOWN:Error received from peer ipv4:172.217.28.42:443 {grpc_status:5, grpc_message:\"Publisher Model `projects/conteudo-autenticare/locations/us-central1/publishers/google/models/gemini-pro-vision` was not found or your project does not have access to it. Please ensure you are using a valid model version. For more information, see: https://cloud.google.com/vertex-ai/generative-ai/docs/learn/model-versions\"}\"\n>\n\nThe above exception was the direct cause of the following exception:\n\nTraceback (most recent call last):\n  File \"/home/rafael/Desktop/projetos/yduqs_back/app/utils/verificaImagemVideo.py\", line 83, in analisar_imagem\n    response = model.generate_content([prompt, image])\n  File \"/home/rafael/.local/lib/python3.9/site-packages/vertexai/generative_models/_generative_models.py\", line 654, in generate_content\n    return self._generate_content(\n  File \"/home/rafael/.local/lib/python3.9/site-packages/vertexai/generative_models/_generative_models.py\", line 779, in _generate_content\n    gapic_response = self._prediction_client.generate_content(request=request)\n  File \"/home/rafael/.local/lib/python3.9/site-packages/google/cloud/aiplatform_v1/services/prediction_service/client.py\", line 2159, in generate_content\n    response = rpc(\n  File \"/home/rafael/.local/lib/python3.9/site-packages/google/api_core/gapic_v1/method.py\", line 131, in __call__\n    return wrapped_func(*args, **kwargs)\n  File \"/home/rafael/.local/lib/python3.9/site-packages/google/api_core/grpc_helpers.py\", line 78, in error_remapped_callable\n    raise exceptions.from_grpc_error(exc) from exc\ngoogle.api_core.exceptions.NotFound: 404 Publisher Model `projects/conteudo-autenticare/locations/us-central1/publishers/google/models/gemini-pro-vision` was not found or your project does not have access to it. Please ensure you are using a valid model version. For more information, see: https://cloud.google.com/vertex-ai/generative-ai/docs/learn/model-versions"}}
{"timestamp": "2025-05-16T02:02:14.936641", "level": "ERROR", "logger": "app.utils.verificaImagemVideo", "message": "Erro ao analisar imagem: 404 Publisher Model `projects/conteudo-autenticare/locations/us-central1/publishers/google/models/gemini-pro-vision` was not found or your project does not have access to it. Please ensure you are using a valid model version. For more information, see: https://cloud.google.com/vertex-ai/generative-ai/docs/learn/model-versions", "exception": {"type": "NotFound", "message": "404 Publisher Model `projects/conteudo-autenticare/locations/us-central1/publishers/google/models/gemini-pro-vision` was not found or your project does not have access to it. Please ensure you are using a valid model version. For more information, see: https://cloud.google.com/vertex-ai/generative-ai/docs/learn/model-versions", "traceback": "Traceback (most recent call last):\n  File \"/home/rafael/.local/lib/python3.9/site-packages/google/api_core/grpc_helpers.py\", line 76, in error_remapped_callable\n    return callable_(*args, **kwargs)\n  File \"/home/rafael/.local/lib/python3.9/site-packages/grpc/_channel.py\", line 1181, in __call__\n    return _end_unary_response_blocking(state, call, False, None)\n  File \"/home/rafael/.local/lib/python3.9/site-packages/grpc/_channel.py\", line 1006, in _end_unary_response_blocking\n    raise _InactiveRpcError(state)  # pytype: disable=not-instantiable\ngrpc._channel._InactiveRpcError: <_InactiveRpcError of RPC that terminated with:\n\tstatus = StatusCode.NOT_FOUND\n\tdetails = \"Publisher Model `projects/conteudo-autenticare/locations/us-central1/publishers/google/models/gemini-pro-vision` was not found or your project does not have access to it. Please ensure you are using a valid model version. For more information, see: https://cloud.google.com/vertex-ai/generative-ai/docs/learn/model-versions\"\n\tdebug_error_string = \"UNKNOWN:Error received from peer ipv4:142.251.128.170:443 {grpc_status:5, grpc_message:\"Publisher Model `projects/conteudo-autenticare/locations/us-central1/publishers/google/models/gemini-pro-vision` was not found or your project does not have access to it. Please ensure you are using a valid model version. For more information, see: https://cloud.google.com/vertex-ai/generative-ai/docs/learn/model-versions\"}\"\n>\n\nThe above exception was the direct cause of the following exception:\n\nTraceback (most recent call last):\n  File \"/home/rafael/Desktop/projetos/yduqs_back/app/utils/verificaImagemVideo.py\", line 83, in analisar_imagem\n    response = model.generate_content([prompt, image])\n  File \"/home/rafael/.local/lib/python3.9/site-packages/vertexai/generative_models/_generative_models.py\", line 654, in generate_content\n    return self._generate_content(\n  File \"/home/rafael/.local/lib/python3.9/site-packages/vertexai/generative_models/_generative_models.py\", line 779, in _generate_content\n    gapic_response = self._prediction_client.generate_content(request=request)\n  File \"/home/rafael/.local/lib/python3.9/site-packages/google/cloud/aiplatform_v1/services/prediction_service/client.py\", line 2159, in generate_content\n    response = rpc(\n  File \"/home/rafael/.local/lib/python3.9/site-packages/google/api_core/gapic_v1/method.py\", line 131, in __call__\n    return wrapped_func(*args, **kwargs)\n  File \"/home/rafael/.local/lib/python3.9/site-packages/google/api_core/grpc_helpers.py\", line 78, in error_remapped_callable\n    raise exceptions.from_grpc_error(exc) from exc\ngoogle.api_core.exceptions.NotFound: 404 Publisher Model `projects/conteudo-autenticare/locations/us-central1/publishers/google/models/gemini-pro-vision` was not found or your project does not have access to it. Please ensure you are using a valid model version. For more information, see: https://cloud.google.com/vertex-ai/generative-ai/docs/learn/model-versions"}}
{"timestamp": "2025-05-16T02:02:17.894439", "level": "ERROR", "logger": "app.utils.verificaImagemVideo", "message": "Erro ao analisar imagem: 404 Publisher Model `projects/conteudo-autenticare/locations/us-central1/publishers/google/models/gemini-pro-vision` was not found or your project does not have access to it. Please ensure you are using a valid model version. For more information, see: https://cloud.google.com/vertex-ai/generative-ai/docs/learn/model-versions", "exception": {"type": "NotFound", "message": "404 Publisher Model `projects/conteudo-autenticare/locations/us-central1/publishers/google/models/gemini-pro-vision` was not found or your project does not have access to it. Please ensure you are using a valid model version. For more information, see: https://cloud.google.com/vertex-ai/generative-ai/docs/learn/model-versions", "traceback": "Traceback (most recent call last):\n  File \"/home/rafael/.local/lib/python3.9/site-packages/google/api_core/grpc_helpers.py\", line 76, in error_remapped_callable\n    return callable_(*args, **kwargs)\n  File \"/home/rafael/.local/lib/python3.9/site-packages/grpc/_channel.py\", line 1181, in __call__\n    return _end_unary_response_blocking(state, call, False, None)\n  File \"/home/rafael/.local/lib/python3.9/site-packages/grpc/_channel.py\", line 1006, in _end_unary_response_blocking\n    raise _InactiveRpcError(state)  # pytype: disable=not-instantiable\ngrpc._channel._InactiveRpcError: <_InactiveRpcError of RPC that terminated with:\n\tstatus = StatusCode.NOT_FOUND\n\tdetails = \"Publisher Model `projects/conteudo-autenticare/locations/us-central1/publishers/google/models/gemini-pro-vision` was not found or your project does not have access to it. Please ensure you are using a valid model version. For more information, see: https://cloud.google.com/vertex-ai/generative-ai/docs/learn/model-versions\"\n\tdebug_error_string = \"UNKNOWN:Error received from peer ipv4:172.217.28.42:443 {grpc_status:5, grpc_message:\"Publisher Model `projects/conteudo-autenticare/locations/us-central1/publishers/google/models/gemini-pro-vision` was not found or your project does not have access to it. Please ensure you are using a valid model version. For more information, see: https://cloud.google.com/vertex-ai/generative-ai/docs/learn/model-versions\"}\"\n>\n\nThe above exception was the direct cause of the following exception:\n\nTraceback (most recent call last):\n  File \"/home/rafael/Desktop/projetos/yduqs_back/app/utils/verificaImagemVideo.py\", line 83, in analisar_imagem\n    response = model.generate_content([prompt, image])\n  File \"/home/rafael/.local/lib/python3.9/site-packages/vertexai/generative_models/_generative_models.py\", line 654, in generate_content\n    return self._generate_content(\n  File \"/home/rafael/.local/lib/python3.9/site-packages/vertexai/generative_models/_generative_models.py\", line 779, in _generate_content\n    gapic_response = self._prediction_client.generate_content(request=request)\n  File \"/home/rafael/.local/lib/python3.9/site-packages/google/cloud/aiplatform_v1/services/prediction_service/client.py\", line 2159, in generate_content\n    response = rpc(\n  File \"/home/rafael/.local/lib/python3.9/site-packages/google/api_core/gapic_v1/method.py\", line 131, in __call__\n    return wrapped_func(*args, **kwargs)\n  File \"/home/rafael/.local/lib/python3.9/site-packages/google/api_core/grpc_helpers.py\", line 78, in error_remapped_callable\n    raise exceptions.from_grpc_error(exc) from exc\ngoogle.api_core.exceptions.NotFound: 404 Publisher Model `projects/conteudo-autenticare/locations/us-central1/publishers/google/models/gemini-pro-vision` was not found or your project does not have access to it. Please ensure you are using a valid model version. For more information, see: https://cloud.google.com/vertex-ai/generative-ai/docs/learn/model-versions"}}
{"timestamp": "2025-05-16T02:02:20.863733", "level": "ERROR", "logger": "app.utils.verificaImagemVideo", "message": "Erro ao analisar imagem: 404 Publisher Model `projects/conteudo-autenticare/locations/us-central1/publishers/google/models/gemini-pro-vision` was not found or your project does not have access to it. Please ensure you are using a valid model version. For more information, see: https://cloud.google.com/vertex-ai/generative-ai/docs/learn/model-versions", "exception": {"type": "NotFound", "message": "404 Publisher Model `projects/conteudo-autenticare/locations/us-central1/publishers/google/models/gemini-pro-vision` was not found or your project does not have access to it. Please ensure you are using a valid model version. For more information, see: https://cloud.google.com/vertex-ai/generative-ai/docs/learn/model-versions", "traceback": "Traceback (most recent call last):\n  File \"/home/rafael/.local/lib/python3.9/site-packages/google/api_core/grpc_helpers.py\", line 76, in error_remapped_callable\n    return callable_(*args, **kwargs)\n  File \"/home/rafael/.local/lib/python3.9/site-packages/grpc/_channel.py\", line 1181, in __call__\n    return _end_unary_response_blocking(state, call, False, None)\n  File \"/home/rafael/.local/lib/python3.9/site-packages/grpc/_channel.py\", line 1006, in _end_unary_response_blocking\n    raise _InactiveRpcError(state)  # pytype: disable=not-instantiable\ngrpc._channel._InactiveRpcError: <_InactiveRpcError of RPC that terminated with:\n\tstatus = StatusCode.NOT_FOUND\n\tdetails = \"Publisher Model `projects/conteudo-autenticare/locations/us-central1/publishers/google/models/gemini-pro-vision` was not found or your project does not have access to it. Please ensure you are using a valid model version. For more information, see: https://cloud.google.com/vertex-ai/generative-ai/docs/learn/model-versions\"\n\tdebug_error_string = \"UNKNOWN:Error received from peer ipv4:172.217.29.106:443 {grpc_status:5, grpc_message:\"Publisher Model `projects/conteudo-autenticare/locations/us-central1/publishers/google/models/gemini-pro-vision` was not found or your project does not have access to it. Please ensure you are using a valid model version. For more information, see: https://cloud.google.com/vertex-ai/generative-ai/docs/learn/model-versions\"}\"\n>\n\nThe above exception was the direct cause of the following exception:\n\nTraceback (most recent call last):\n  File \"/home/rafael/Desktop/projetos/yduqs_back/app/utils/verificaImagemVideo.py\", line 83, in analisar_imagem\n    response = model.generate_content([prompt, image])\n  File \"/home/rafael/.local/lib/python3.9/site-packages/vertexai/generative_models/_generative_models.py\", line 654, in generate_content\n    return self._generate_content(\n  File \"/home/rafael/.local/lib/python3.9/site-packages/vertexai/generative_models/_generative_models.py\", line 779, in _generate_content\n    gapic_response = self._prediction_client.generate_content(request=request)\n  File \"/home/rafael/.local/lib/python3.9/site-packages/google/cloud/aiplatform_v1/services/prediction_service/client.py\", line 2159, in generate_content\n    response = rpc(\n  File \"/home/rafael/.local/lib/python3.9/site-packages/google/api_core/gapic_v1/method.py\", line 131, in __call__\n    return wrapped_func(*args, **kwargs)\n  File \"/home/rafael/.local/lib/python3.9/site-packages/google/api_core/grpc_helpers.py\", line 78, in error_remapped_callable\n    raise exceptions.from_grpc_error(exc) from exc\ngoogle.api_core.exceptions.NotFound: 404 Publisher Model `projects/conteudo-autenticare/locations/us-central1/publishers/google/models/gemini-pro-vision` was not found or your project does not have access to it. Please ensure you are using a valid model version. For more information, see: https://cloud.google.com/vertex-ai/generative-ai/docs/learn/model-versions"}}
{"timestamp": "2025-05-16T02:02:23.084632", "level": "ERROR", "logger": "app.utils.verificaImagemVideo", "message": "Erro ao analisar imagem: 404 Publisher Model `projects/conteudo-autenticare/locations/us-central1/publishers/google/models/gemini-pro-vision` was not found or your project does not have access to it. Please ensure you are using a valid model version. For more information, see: https://cloud.google.com/vertex-ai/generative-ai/docs/learn/model-versions", "exception": {"type": "NotFound", "message": "404 Publisher Model `projects/conteudo-autenticare/locations/us-central1/publishers/google/models/gemini-pro-vision` was not found or your project does not have access to it. Please ensure you are using a valid model version. For more information, see: https://cloud.google.com/vertex-ai/generative-ai/docs/learn/model-versions", "traceback": "Traceback (most recent call last):\n  File \"/home/rafael/.local/lib/python3.9/site-packages/google/api_core/grpc_helpers.py\", line 76, in error_remapped_callable\n    return callable_(*args, **kwargs)\n  File \"/home/rafael/.local/lib/python3.9/site-packages/grpc/_channel.py\", line 1181, in __call__\n    return _end_unary_response_blocking(state, call, False, None)\n  File \"/home/rafael/.local/lib/python3.9/site-packages/grpc/_channel.py\", line 1006, in _end_unary_response_blocking\n    raise _InactiveRpcError(state)  # pytype: disable=not-instantiable\ngrpc._channel._InactiveRpcError: <_InactiveRpcError of RPC that terminated with:\n\tstatus = StatusCode.NOT_FOUND\n\tdetails = \"Publisher Model `projects/conteudo-autenticare/locations/us-central1/publishers/google/models/gemini-pro-vision` was not found or your project does not have access to it. Please ensure you are using a valid model version. For more information, see: https://cloud.google.com/vertex-ai/generative-ai/docs/learn/model-versions\"\n\tdebug_error_string = \"UNKNOWN:Error received from peer ipv4:172.217.29.106:443 {grpc_status:5, grpc_message:\"Publisher Model `projects/conteudo-autenticare/locations/us-central1/publishers/google/models/gemini-pro-vision` was not found or your project does not have access to it. Please ensure you are using a valid model version. For more information, see: https://cloud.google.com/vertex-ai/generative-ai/docs/learn/model-versions\"}\"\n>\n\nThe above exception was the direct cause of the following exception:\n\nTraceback (most recent call last):\n  File \"/home/rafael/Desktop/projetos/yduqs_back/app/utils/verificaImagemVideo.py\", line 83, in analisar_imagem\n    response = model.generate_content([prompt, image])\n  File \"/home/rafael/.local/lib/python3.9/site-packages/vertexai/generative_models/_generative_models.py\", line 654, in generate_content\n    return self._generate_content(\n  File \"/home/rafael/.local/lib/python3.9/site-packages/vertexai/generative_models/_generative_models.py\", line 779, in _generate_content\n    gapic_response = self._prediction_client.generate_content(request=request)\n  File \"/home/rafael/.local/lib/python3.9/site-packages/google/cloud/aiplatform_v1/services/prediction_service/client.py\", line 2159, in generate_content\n    response = rpc(\n  File \"/home/rafael/.local/lib/python3.9/site-packages/google/api_core/gapic_v1/method.py\", line 131, in __call__\n    return wrapped_func(*args, **kwargs)\n  File \"/home/rafael/.local/lib/python3.9/site-packages/google/api_core/grpc_helpers.py\", line 78, in error_remapped_callable\n    raise exceptions.from_grpc_error(exc) from exc\ngoogle.api_core.exceptions.NotFound: 404 Publisher Model `projects/conteudo-autenticare/locations/us-central1/publishers/google/models/gemini-pro-vision` was not found or your project does not have access to it. Please ensure you are using a valid model version. For more information, see: https://cloud.google.com/vertex-ai/generative-ai/docs/learn/model-versions"}}
{"timestamp": "2025-05-16T02:02:26.189441", "level": "ERROR", "logger": "app.utils.verificaImagemVideo", "message": "Erro ao analisar imagem: 404 Publisher Model `projects/conteudo-autenticare/locations/us-central1/publishers/google/models/gemini-pro-vision` was not found or your project does not have access to it. Please ensure you are using a valid model version. For more information, see: https://cloud.google.com/vertex-ai/generative-ai/docs/learn/model-versions", "exception": {"type": "NotFound", "message": "404 Publisher Model `projects/conteudo-autenticare/locations/us-central1/publishers/google/models/gemini-pro-vision` was not found or your project does not have access to it. Please ensure you are using a valid model version. For more information, see: https://cloud.google.com/vertex-ai/generative-ai/docs/learn/model-versions", "traceback": "Traceback (most recent call last):\n  File \"/home/rafael/.local/lib/python3.9/site-packages/google/api_core/grpc_helpers.py\", line 76, in error_remapped_callable\n    return callable_(*args, **kwargs)\n  File \"/home/rafael/.local/lib/python3.9/site-packages/grpc/_channel.py\", line 1181, in __call__\n    return _end_unary_response_blocking(state, call, False, None)\n  File \"/home/rafael/.local/lib/python3.9/site-packages/grpc/_channel.py\", line 1006, in _end_unary_response_blocking\n    raise _InactiveRpcError(state)  # pytype: disable=not-instantiable\ngrpc._channel._InactiveRpcError: <_InactiveRpcError of RPC that terminated with:\n\tstatus = StatusCode.NOT_FOUND\n\tdetails = \"Publisher Model `projects/conteudo-autenticare/locations/us-central1/publishers/google/models/gemini-pro-vision` was not found or your project does not have access to it. Please ensure you are using a valid model version. For more information, see: https://cloud.google.com/vertex-ai/generative-ai/docs/learn/model-versions\"\n\tdebug_error_string = \"UNKNOWN:Error received from peer ipv4:172.217.30.10:443 {grpc_message:\"Publisher Model `projects/conteudo-autenticare/locations/us-central1/publishers/google/models/gemini-pro-vision` was not found or your project does not have access to it. Please ensure you are using a valid model version. For more information, see: https://cloud.google.com/vertex-ai/generative-ai/docs/learn/model-versions\", grpc_status:5}\"\n>\n\nThe above exception was the direct cause of the following exception:\n\nTraceback (most recent call last):\n  File \"/home/rafael/Desktop/projetos/yduqs_back/app/utils/verificaImagemVideo.py\", line 83, in analisar_imagem\n    response = model.generate_content([prompt, image])\n  File \"/home/rafael/.local/lib/python3.9/site-packages/vertexai/generative_models/_generative_models.py\", line 654, in generate_content\n    return self._generate_content(\n  File \"/home/rafael/.local/lib/python3.9/site-packages/vertexai/generative_models/_generative_models.py\", line 779, in _generate_content\n    gapic_response = self._prediction_client.generate_content(request=request)\n  File \"/home/rafael/.local/lib/python3.9/site-packages/google/cloud/aiplatform_v1/services/prediction_service/client.py\", line 2159, in generate_content\n    response = rpc(\n  File \"/home/rafael/.local/lib/python3.9/site-packages/google/api_core/gapic_v1/method.py\", line 131, in __call__\n    return wrapped_func(*args, **kwargs)\n  File \"/home/rafael/.local/lib/python3.9/site-packages/google/api_core/grpc_helpers.py\", line 78, in error_remapped_callable\n    raise exceptions.from_grpc_error(exc) from exc\ngoogle.api_core.exceptions.NotFound: 404 Publisher Model `projects/conteudo-autenticare/locations/us-central1/publishers/google/models/gemini-pro-vision` was not found or your project does not have access to it. Please ensure you are using a valid model version. For more information, see: https://cloud.google.com/vertex-ai/generative-ai/docs/learn/model-versions"}}
{"timestamp": "2025-05-16T02:02:31.520730", "level": "ERROR", "logger": "app.utils.verificaImagemVideo", "message": "Erro ao analisar imagem: 404 Publisher Model `projects/conteudo-autenticare/locations/us-central1/publishers/google/models/gemini-pro-vision` was not found or your project does not have access to it. Please ensure you are using a valid model version. For more information, see: https://cloud.google.com/vertex-ai/generative-ai/docs/learn/model-versions", "exception": {"type": "NotFound", "message": "404 Publisher Model `projects/conteudo-autenticare/locations/us-central1/publishers/google/models/gemini-pro-vision` was not found or your project does not have access to it. Please ensure you are using a valid model version. For more information, see: https://cloud.google.com/vertex-ai/generative-ai/docs/learn/model-versions", "traceback": "Traceback (most recent call last):\n  File \"/home/rafael/.local/lib/python3.9/site-packages/google/api_core/grpc_helpers.py\", line 76, in error_remapped_callable\n    return callable_(*args, **kwargs)\n  File \"/home/rafael/.local/lib/python3.9/site-packages/grpc/_channel.py\", line 1181, in __call__\n    return _end_unary_response_blocking(state, call, False, None)\n  File \"/home/rafael/.local/lib/python3.9/site-packages/grpc/_channel.py\", line 1006, in _end_unary_response_blocking\n    raise _InactiveRpcError(state)  # pytype: disable=not-instantiable\ngrpc._channel._InactiveRpcError: <_InactiveRpcError of RPC that terminated with:\n\tstatus = StatusCode.NOT_FOUND\n\tdetails = \"Publisher Model `projects/conteudo-autenticare/locations/us-central1/publishers/google/models/gemini-pro-vision` was not found or your project does not have access to it. Please ensure you are using a valid model version. For more information, see: https://cloud.google.com/vertex-ai/generative-ai/docs/learn/model-versions\"\n\tdebug_error_string = \"UNKNOWN:Error received from peer ipv4:142.251.132.202:443 {grpc_status:5, grpc_message:\"Publisher Model `projects/conteudo-autenticare/locations/us-central1/publishers/google/models/gemini-pro-vision` was not found or your project does not have access to it. Please ensure you are using a valid model version. For more information, see: https://cloud.google.com/vertex-ai/generative-ai/docs/learn/model-versions\"}\"\n>\n\nThe above exception was the direct cause of the following exception:\n\nTraceback (most recent call last):\n  File \"/home/rafael/Desktop/projetos/yduqs_back/app/utils/verificaImagemVideo.py\", line 83, in analisar_imagem\n    response = model.generate_content([prompt, image])\n  File \"/home/rafael/.local/lib/python3.9/site-packages/vertexai/generative_models/_generative_models.py\", line 654, in generate_content\n    return self._generate_content(\n  File \"/home/rafael/.local/lib/python3.9/site-packages/vertexai/generative_models/_generative_models.py\", line 779, in _generate_content\n    gapic_response = self._prediction_client.generate_content(request=request)\n  File \"/home/rafael/.local/lib/python3.9/site-packages/google/cloud/aiplatform_v1/services/prediction_service/client.py\", line 2159, in generate_content\n    response = rpc(\n  File \"/home/rafael/.local/lib/python3.9/site-packages/google/api_core/gapic_v1/method.py\", line 131, in __call__\n    return wrapped_func(*args, **kwargs)\n  File \"/home/rafael/.local/lib/python3.9/site-packages/google/api_core/grpc_helpers.py\", line 78, in error_remapped_callable\n    raise exceptions.from_grpc_error(exc) from exc\ngoogle.api_core.exceptions.NotFound: 404 Publisher Model `projects/conteudo-autenticare/locations/us-central1/publishers/google/models/gemini-pro-vision` was not found or your project does not have access to it. Please ensure you are using a valid model version. For more information, see: https://cloud.google.com/vertex-ai/generative-ai/docs/learn/model-versions"}}
{"timestamp": "2025-05-16T02:02:33.401232", "level": "ERROR", "logger": "app.utils.verificaImagemVideo", "message": "Erro ao analisar imagem: 404 Publisher Model `projects/conteudo-autenticare/locations/us-central1/publishers/google/models/gemini-pro-vision` was not found or your project does not have access to it. Please ensure you are using a valid model version. For more information, see: https://cloud.google.com/vertex-ai/generative-ai/docs/learn/model-versions", "exception": {"type": "NotFound", "message": "404 Publisher Model `projects/conteudo-autenticare/locations/us-central1/publishers/google/models/gemini-pro-vision` was not found or your project does not have access to it. Please ensure you are using a valid model version. For more information, see: https://cloud.google.com/vertex-ai/generative-ai/docs/learn/model-versions", "traceback": "Traceback (most recent call last):\n  File \"/home/rafael/.local/lib/python3.9/site-packages/google/api_core/grpc_helpers.py\", line 76, in error_remapped_callable\n    return callable_(*args, **kwargs)\n  File \"/home/rafael/.local/lib/python3.9/site-packages/grpc/_channel.py\", line 1181, in __call__\n    return _end_unary_response_blocking(state, call, False, None)\n  File \"/home/rafael/.local/lib/python3.9/site-packages/grpc/_channel.py\", line 1006, in _end_unary_response_blocking\n    raise _InactiveRpcError(state)  # pytype: disable=not-instantiable\ngrpc._channel._InactiveRpcError: <_InactiveRpcError of RPC that terminated with:\n\tstatus = StatusCode.NOT_FOUND\n\tdetails = \"Publisher Model `projects/conteudo-autenticare/locations/us-central1/publishers/google/models/gemini-pro-vision` was not found or your project does not have access to it. Please ensure you are using a valid model version. For more information, see: https://cloud.google.com/vertex-ai/generative-ai/docs/learn/model-versions\"\n\tdebug_error_string = \"UNKNOWN:Error received from peer ipv4:172.217.28.170:443 {grpc_status:5, grpc_message:\"Publisher Model `projects/conteudo-autenticare/locations/us-central1/publishers/google/models/gemini-pro-vision` was not found or your project does not have access to it. Please ensure you are using a valid model version. For more information, see: https://cloud.google.com/vertex-ai/generative-ai/docs/learn/model-versions\"}\"\n>\n\nThe above exception was the direct cause of the following exception:\n\nTraceback (most recent call last):\n  File \"/home/rafael/Desktop/projetos/yduqs_back/app/utils/verificaImagemVideo.py\", line 83, in analisar_imagem\n    response = model.generate_content([prompt, image])\n  File \"/home/rafael/.local/lib/python3.9/site-packages/vertexai/generative_models/_generative_models.py\", line 654, in generate_content\n    return self._generate_content(\n  File \"/home/rafael/.local/lib/python3.9/site-packages/vertexai/generative_models/_generative_models.py\", line 779, in _generate_content\n    gapic_response = self._prediction_client.generate_content(request=request)\n  File \"/home/rafael/.local/lib/python3.9/site-packages/google/cloud/aiplatform_v1/services/prediction_service/client.py\", line 2159, in generate_content\n    response = rpc(\n  File \"/home/rafael/.local/lib/python3.9/site-packages/google/api_core/gapic_v1/method.py\", line 131, in __call__\n    return wrapped_func(*args, **kwargs)\n  File \"/home/rafael/.local/lib/python3.9/site-packages/google/api_core/grpc_helpers.py\", line 78, in error_remapped_callable\n    raise exceptions.from_grpc_error(exc) from exc\ngoogle.api_core.exceptions.NotFound: 404 Publisher Model `projects/conteudo-autenticare/locations/us-central1/publishers/google/models/gemini-pro-vision` was not found or your project does not have access to it. Please ensure you are using a valid model version. For more information, see: https://cloud.google.com/vertex-ai/generative-ai/docs/learn/model-versions"}}
{"timestamp": "2025-05-16T02:02:35.195331", "level": "ERROR", "logger": "app.utils.verificaImagemVideo", "message": "Erro ao analisar imagem: 404 Publisher Model `projects/conteudo-autenticare/locations/us-central1/publishers/google/models/gemini-pro-vision` was not found or your project does not have access to it. Please ensure you are using a valid model version. For more information, see: https://cloud.google.com/vertex-ai/generative-ai/docs/learn/model-versions", "exception": {"type": "NotFound", "message": "404 Publisher Model `projects/conteudo-autenticare/locations/us-central1/publishers/google/models/gemini-pro-vision` was not found or your project does not have access to it. Please ensure you are using a valid model version. For more information, see: https://cloud.google.com/vertex-ai/generative-ai/docs/learn/model-versions", "traceback": "Traceback (most recent call last):\n  File \"/home/rafael/.local/lib/python3.9/site-packages/google/api_core/grpc_helpers.py\", line 76, in error_remapped_callable\n    return callable_(*args, **kwargs)\n  File \"/home/rafael/.local/lib/python3.9/site-packages/grpc/_channel.py\", line 1181, in __call__\n    return _end_unary_response_blocking(state, call, False, None)\n  File \"/home/rafael/.local/lib/python3.9/site-packages/grpc/_channel.py\", line 1006, in _end_unary_response_blocking\n    raise _InactiveRpcError(state)  # pytype: disable=not-instantiable\ngrpc._channel._InactiveRpcError: <_InactiveRpcError of RPC that terminated with:\n\tstatus = StatusCode.NOT_FOUND\n\tdetails = \"Publisher Model `projects/conteudo-autenticare/locations/us-central1/publishers/google/models/gemini-pro-vision` was not found or your project does not have access to it. Please ensure you are using a valid model version. For more information, see: https://cloud.google.com/vertex-ai/generative-ai/docs/learn/model-versions\"\n\tdebug_error_string = \"UNKNOWN:Error received from peer ipv4:172.217.28.170:443 {grpc_message:\"Publisher Model `projects/conteudo-autenticare/locations/us-central1/publishers/google/models/gemini-pro-vision` was not found or your project does not have access to it. Please ensure you are using a valid model version. For more information, see: https://cloud.google.com/vertex-ai/generative-ai/docs/learn/model-versions\", grpc_status:5}\"\n>\n\nThe above exception was the direct cause of the following exception:\n\nTraceback (most recent call last):\n  File \"/home/rafael/Desktop/projetos/yduqs_back/app/utils/verificaImagemVideo.py\", line 83, in analisar_imagem\n    response = model.generate_content([prompt, image])\n  File \"/home/rafael/.local/lib/python3.9/site-packages/vertexai/generative_models/_generative_models.py\", line 654, in generate_content\n    return self._generate_content(\n  File \"/home/rafael/.local/lib/python3.9/site-packages/vertexai/generative_models/_generative_models.py\", line 779, in _generate_content\n    gapic_response = self._prediction_client.generate_content(request=request)\n  File \"/home/rafael/.local/lib/python3.9/site-packages/google/cloud/aiplatform_v1/services/prediction_service/client.py\", line 2159, in generate_content\n    response = rpc(\n  File \"/home/rafael/.local/lib/python3.9/site-packages/google/api_core/gapic_v1/method.py\", line 131, in __call__\n    return wrapped_func(*args, **kwargs)\n  File \"/home/rafael/.local/lib/python3.9/site-packages/google/api_core/grpc_helpers.py\", line 78, in error_remapped_callable\n    raise exceptions.from_grpc_error(exc) from exc\ngoogle.api_core.exceptions.NotFound: 404 Publisher Model `projects/conteudo-autenticare/locations/us-central1/publishers/google/models/gemini-pro-vision` was not found or your project does not have access to it. Please ensure you are using a valid model version. For more information, see: https://cloud.google.com/vertex-ai/generative-ai/docs/learn/model-versions"}}
{"timestamp": "2025-05-16T02:02:42.510639", "level": "ERROR", "logger": "app.utils.verificaImagemVideo", "message": "Erro ao analisar imagem: 404 Publisher Model `projects/conteudo-autenticare/locations/us-central1/publishers/google/models/gemini-pro-vision` was not found or your project does not have access to it. Please ensure you are using a valid model version. For more information, see: https://cloud.google.com/vertex-ai/generative-ai/docs/learn/model-versions", "exception": {"type": "NotFound", "message": "404 Publisher Model `projects/conteudo-autenticare/locations/us-central1/publishers/google/models/gemini-pro-vision` was not found or your project does not have access to it. Please ensure you are using a valid model version. For more information, see: https://cloud.google.com/vertex-ai/generative-ai/docs/learn/model-versions", "traceback": "Traceback (most recent call last):\n  File \"/home/rafael/.local/lib/python3.9/site-packages/google/api_core/grpc_helpers.py\", line 76, in error_remapped_callable\n    return callable_(*args, **kwargs)\n  File \"/home/rafael/.local/lib/python3.9/site-packages/grpc/_channel.py\", line 1181, in __call__\n    return _end_unary_response_blocking(state, call, False, None)\n  File \"/home/rafael/.local/lib/python3.9/site-packages/grpc/_channel.py\", line 1006, in _end_unary_response_blocking\n    raise _InactiveRpcError(state)  # pytype: disable=not-instantiable\ngrpc._channel._InactiveRpcError: <_InactiveRpcError of RPC that terminated with:\n\tstatus = StatusCode.NOT_FOUND\n\tdetails = \"Publisher Model `projects/conteudo-autenticare/locations/us-central1/publishers/google/models/gemini-pro-vision` was not found or your project does not have access to it. Please ensure you are using a valid model version. For more information, see: https://cloud.google.com/vertex-ai/generative-ai/docs/learn/model-versions\"\n\tdebug_error_string = \"UNKNOWN:Error received from peer ipv4:142.251.132.202:443 {grpc_status:5, grpc_message:\"Publisher Model `projects/conteudo-autenticare/locations/us-central1/publishers/google/models/gemini-pro-vision` was not found or your project does not have access to it. Please ensure you are using a valid model version. For more information, see: https://cloud.google.com/vertex-ai/generative-ai/docs/learn/model-versions\"}\"\n>\n\nThe above exception was the direct cause of the following exception:\n\nTraceback (most recent call last):\n  File \"/home/rafael/Desktop/projetos/yduqs_back/app/utils/verificaImagemVideo.py\", line 83, in analisar_imagem\n    response = model.generate_content([prompt, image])\n  File \"/home/rafael/.local/lib/python3.9/site-packages/vertexai/generative_models/_generative_models.py\", line 654, in generate_content\n    return self._generate_content(\n  File \"/home/rafael/.local/lib/python3.9/site-packages/vertexai/generative_models/_generative_models.py\", line 779, in _generate_content\n    gapic_response = self._prediction_client.generate_content(request=request)\n  File \"/home/rafael/.local/lib/python3.9/site-packages/google/cloud/aiplatform_v1/services/prediction_service/client.py\", line 2159, in generate_content\n    response = rpc(\n  File \"/home/rafael/.local/lib/python3.9/site-packages/google/api_core/gapic_v1/method.py\", line 131, in __call__\n    return wrapped_func(*args, **kwargs)\n  File \"/home/rafael/.local/lib/python3.9/site-packages/google/api_core/grpc_helpers.py\", line 78, in error_remapped_callable\n    raise exceptions.from_grpc_error(exc) from exc\ngoogle.api_core.exceptions.NotFound: 404 Publisher Model `projects/conteudo-autenticare/locations/us-central1/publishers/google/models/gemini-pro-vision` was not found or your project does not have access to it. Please ensure you are using a valid model version. For more information, see: https://cloud.google.com/vertex-ai/generative-ai/docs/learn/model-versions"}}
{"timestamp": "2025-05-16T02:02:44.602341", "level": "ERROR", "logger": "app.utils.verificaImagemVideo", "message": "Erro ao analisar imagem: 404 Publisher Model `projects/conteudo-autenticare/locations/us-central1/publishers/google/models/gemini-pro-vision` was not found or your project does not have access to it. Please ensure you are using a valid model version. For more information, see: https://cloud.google.com/vertex-ai/generative-ai/docs/learn/model-versions", "exception": {"type": "NotFound", "message": "404 Publisher Model `projects/conteudo-autenticare/locations/us-central1/publishers/google/models/gemini-pro-vision` was not found or your project does not have access to it. Please ensure you are using a valid model version. For more information, see: https://cloud.google.com/vertex-ai/generative-ai/docs/learn/model-versions", "traceback": "Traceback (most recent call last):\n  File \"/home/rafael/.local/lib/python3.9/site-packages/google/api_core/grpc_helpers.py\", line 76, in error_remapped_callable\n    return callable_(*args, **kwargs)\n  File \"/home/rafael/.local/lib/python3.9/site-packages/grpc/_channel.py\", line 1181, in __call__\n    return _end_unary_response_blocking(state, call, False, None)\n  File \"/home/rafael/.local/lib/python3.9/site-packages/grpc/_channel.py\", line 1006, in _end_unary_response_blocking\n    raise _InactiveRpcError(state)  # pytype: disable=not-instantiable\ngrpc._channel._InactiveRpcError: <_InactiveRpcError of RPC that terminated with:\n\tstatus = StatusCode.NOT_FOUND\n\tdetails = \"Publisher Model `projects/conteudo-autenticare/locations/us-central1/publishers/google/models/gemini-pro-vision` was not found or your project does not have access to it. Please ensure you are using a valid model version. For more information, see: https://cloud.google.com/vertex-ai/generative-ai/docs/learn/model-versions\"\n\tdebug_error_string = \"UNKNOWN:Error received from peer ipv4:172.217.28.170:443 {grpc_status:5, grpc_message:\"Publisher Model `projects/conteudo-autenticare/locations/us-central1/publishers/google/models/gemini-pro-vision` was not found or your project does not have access to it. Please ensure you are using a valid model version. For more information, see: https://cloud.google.com/vertex-ai/generative-ai/docs/learn/model-versions\"}\"\n>\n\nThe above exception was the direct cause of the following exception:\n\nTraceback (most recent call last):\n  File \"/home/rafael/Desktop/projetos/yduqs_back/app/utils/verificaImagemVideo.py\", line 83, in analisar_imagem\n    response = model.generate_content([prompt, image])\n  File \"/home/rafael/.local/lib/python3.9/site-packages/vertexai/generative_models/_generative_models.py\", line 654, in generate_content\n    return self._generate_content(\n  File \"/home/rafael/.local/lib/python3.9/site-packages/vertexai/generative_models/_generative_models.py\", line 779, in _generate_content\n    gapic_response = self._prediction_client.generate_content(request=request)\n  File \"/home/rafael/.local/lib/python3.9/site-packages/google/cloud/aiplatform_v1/services/prediction_service/client.py\", line 2159, in generate_content\n    response = rpc(\n  File \"/home/rafael/.local/lib/python3.9/site-packages/google/api_core/gapic_v1/method.py\", line 131, in __call__\n    return wrapped_func(*args, **kwargs)\n  File \"/home/rafael/.local/lib/python3.9/site-packages/google/api_core/grpc_helpers.py\", line 78, in error_remapped_callable\n    raise exceptions.from_grpc_error(exc) from exc\ngoogle.api_core.exceptions.NotFound: 404 Publisher Model `projects/conteudo-autenticare/locations/us-central1/publishers/google/models/gemini-pro-vision` was not found or your project does not have access to it. Please ensure you are using a valid model version. For more information, see: https://cloud.google.com/vertex-ai/generative-ai/docs/learn/model-versions"}}
{"timestamp": "2025-05-16T02:02:47.292150", "level": "ERROR", "logger": "app.utils.verificaImagemVideo", "message": "Erro ao analisar imagem: 404 Publisher Model `projects/conteudo-autenticare/locations/us-central1/publishers/google/models/gemini-pro-vision` was not found or your project does not have access to it. Please ensure you are using a valid model version. For more information, see: https://cloud.google.com/vertex-ai/generative-ai/docs/learn/model-versions", "exception": {"type": "NotFound", "message": "404 Publisher Model `projects/conteudo-autenticare/locations/us-central1/publishers/google/models/gemini-pro-vision` was not found or your project does not have access to it. Please ensure you are using a valid model version. For more information, see: https://cloud.google.com/vertex-ai/generative-ai/docs/learn/model-versions", "traceback": "Traceback (most recent call last):\n  File \"/home/rafael/.local/lib/python3.9/site-packages/google/api_core/grpc_helpers.py\", line 76, in error_remapped_callable\n    return callable_(*args, **kwargs)\n  File \"/home/rafael/.local/lib/python3.9/site-packages/grpc/_channel.py\", line 1181, in __call__\n    return _end_unary_response_blocking(state, call, False, None)\n  File \"/home/rafael/.local/lib/python3.9/site-packages/grpc/_channel.py\", line 1006, in _end_unary_response_blocking\n    raise _InactiveRpcError(state)  # pytype: disable=not-instantiable\ngrpc._channel._InactiveRpcError: <_InactiveRpcError of RPC that terminated with:\n\tstatus = StatusCode.NOT_FOUND\n\tdetails = \"Publisher Model `projects/conteudo-autenticare/locations/us-central1/publishers/google/models/gemini-pro-vision` was not found or your project does not have access to it. Please ensure you are using a valid model version. For more information, see: https://cloud.google.com/vertex-ai/generative-ai/docs/learn/model-versions\"\n\tdebug_error_string = \"UNKNOWN:Error received from peer ipv4:172.217.29.170:443 {grpc_message:\"Publisher Model `projects/conteudo-autenticare/locations/us-central1/publishers/google/models/gemini-pro-vision` was not found or your project does not have access to it. Please ensure you are using a valid model version. For more information, see: https://cloud.google.com/vertex-ai/generative-ai/docs/learn/model-versions\", grpc_status:5}\"\n>\n\nThe above exception was the direct cause of the following exception:\n\nTraceback (most recent call last):\n  File \"/home/rafael/Desktop/projetos/yduqs_back/app/utils/verificaImagemVideo.py\", line 83, in analisar_imagem\n    response = model.generate_content([prompt, image])\n  File \"/home/rafael/.local/lib/python3.9/site-packages/vertexai/generative_models/_generative_models.py\", line 654, in generate_content\n    return self._generate_content(\n  File \"/home/rafael/.local/lib/python3.9/site-packages/vertexai/generative_models/_generative_models.py\", line 779, in _generate_content\n    gapic_response = self._prediction_client.generate_content(request=request)\n  File \"/home/rafael/.local/lib/python3.9/site-packages/google/cloud/aiplatform_v1/services/prediction_service/client.py\", line 2159, in generate_content\n    response = rpc(\n  File \"/home/rafael/.local/lib/python3.9/site-packages/google/api_core/gapic_v1/method.py\", line 131, in __call__\n    return wrapped_func(*args, **kwargs)\n  File \"/home/rafael/.local/lib/python3.9/site-packages/google/api_core/grpc_helpers.py\", line 78, in error_remapped_callable\n    raise exceptions.from_grpc_error(exc) from exc\ngoogle.api_core.exceptions.NotFound: 404 Publisher Model `projects/conteudo-autenticare/locations/us-central1/publishers/google/models/gemini-pro-vision` was not found or your project does not have access to it. Please ensure you are using a valid model version. For more information, see: https://cloud.google.com/vertex-ai/generative-ai/docs/learn/model-versions"}}
{"timestamp": "2025-05-16T02:02:49.495469", "level": "ERROR", "logger": "app.utils.verificaImagemVideo", "message": "Erro ao analisar imagem: 404 Publisher Model `projects/conteudo-autenticare/locations/us-central1/publishers/google/models/gemini-pro-vision` was not found or your project does not have access to it. Please ensure you are using a valid model version. For more information, see: https://cloud.google.com/vertex-ai/generative-ai/docs/learn/model-versions", "exception": {"type": "NotFound", "message": "404 Publisher Model `projects/conteudo-autenticare/locations/us-central1/publishers/google/models/gemini-pro-vision` was not found or your project does not have access to it. Please ensure you are using a valid model version. For more information, see: https://cloud.google.com/vertex-ai/generative-ai/docs/learn/model-versions", "traceback": "Traceback (most recent call last):\n  File \"/home/rafael/.local/lib/python3.9/site-packages/google/api_core/grpc_helpers.py\", line 76, in error_remapped_callable\n    return callable_(*args, **kwargs)\n  File \"/home/rafael/.local/lib/python3.9/site-packages/grpc/_channel.py\", line 1181, in __call__\n    return _end_unary_response_blocking(state, call, False, None)\n  File \"/home/rafael/.local/lib/python3.9/site-packages/grpc/_channel.py\", line 1006, in _end_unary_response_blocking\n    raise _InactiveRpcError(state)  # pytype: disable=not-instantiable\ngrpc._channel._InactiveRpcError: <_InactiveRpcError of RPC that terminated with:\n\tstatus = StatusCode.NOT_FOUND\n\tdetails = \"Publisher Model `projects/conteudo-autenticare/locations/us-central1/publishers/google/models/gemini-pro-vision` was not found or your project does not have access to it. Please ensure you are using a valid model version. For more information, see: https://cloud.google.com/vertex-ai/generative-ai/docs/learn/model-versions\"\n\tdebug_error_string = \"UNKNOWN:Error received from peer ipv4:172.217.29.234:443 {grpc_status:5, grpc_message:\"Publisher Model `projects/conteudo-autenticare/locations/us-central1/publishers/google/models/gemini-pro-vision` was not found or your project does not have access to it. Please ensure you are using a valid model version. For more information, see: https://cloud.google.com/vertex-ai/generative-ai/docs/learn/model-versions\"}\"\n>\n\nThe above exception was the direct cause of the following exception:\n\nTraceback (most recent call last):\n  File \"/home/rafael/Desktop/projetos/yduqs_back/app/utils/verificaImagemVideo.py\", line 83, in analisar_imagem\n    response = model.generate_content([prompt, image])\n  File \"/home/rafael/.local/lib/python3.9/site-packages/vertexai/generative_models/_generative_models.py\", line 654, in generate_content\n    return self._generate_content(\n  File \"/home/rafael/.local/lib/python3.9/site-packages/vertexai/generative_models/_generative_models.py\", line 779, in _generate_content\n    gapic_response = self._prediction_client.generate_content(request=request)\n  File \"/home/rafael/.local/lib/python3.9/site-packages/google/cloud/aiplatform_v1/services/prediction_service/client.py\", line 2159, in generate_content\n    response = rpc(\n  File \"/home/rafael/.local/lib/python3.9/site-packages/google/api_core/gapic_v1/method.py\", line 131, in __call__\n    return wrapped_func(*args, **kwargs)\n  File \"/home/rafael/.local/lib/python3.9/site-packages/google/api_core/grpc_helpers.py\", line 78, in error_remapped_callable\n    raise exceptions.from_grpc_error(exc) from exc\ngoogle.api_core.exceptions.NotFound: 404 Publisher Model `projects/conteudo-autenticare/locations/us-central1/publishers/google/models/gemini-pro-vision` was not found or your project does not have access to it. Please ensure you are using a valid model version. For more information, see: https://cloud.google.com/vertex-ai/generative-ai/docs/learn/model-versions"}}
{"timestamp": "2025-05-16T02:02:51.472497", "level": "ERROR", "logger": "app.utils.verificaImagemVideo", "message": "Erro ao analisar imagem: 404 Publisher Model `projects/conteudo-autenticare/locations/us-central1/publishers/google/models/gemini-pro-vision` was not found or your project does not have access to it. Please ensure you are using a valid model version. For more information, see: https://cloud.google.com/vertex-ai/generative-ai/docs/learn/model-versions", "exception": {"type": "NotFound", "message": "404 Publisher Model `projects/conteudo-autenticare/locations/us-central1/publishers/google/models/gemini-pro-vision` was not found or your project does not have access to it. Please ensure you are using a valid model version. For more information, see: https://cloud.google.com/vertex-ai/generative-ai/docs/learn/model-versions", "traceback": "Traceback (most recent call last):\n  File \"/home/rafael/.local/lib/python3.9/site-packages/google/api_core/grpc_helpers.py\", line 76, in error_remapped_callable\n    return callable_(*args, **kwargs)\n  File \"/home/rafael/.local/lib/python3.9/site-packages/grpc/_channel.py\", line 1181, in __call__\n    return _end_unary_response_blocking(state, call, False, None)\n  File \"/home/rafael/.local/lib/python3.9/site-packages/grpc/_channel.py\", line 1006, in _end_unary_response_blocking\n    raise _InactiveRpcError(state)  # pytype: disable=not-instantiable\ngrpc._channel._InactiveRpcError: <_InactiveRpcError of RPC that terminated with:\n\tstatus = StatusCode.NOT_FOUND\n\tdetails = \"Publisher Model `projects/conteudo-autenticare/locations/us-central1/publishers/google/models/gemini-pro-vision` was not found or your project does not have access to it. Please ensure you are using a valid model version. For more information, see: https://cloud.google.com/vertex-ai/generative-ai/docs/learn/model-versions\"\n\tdebug_error_string = \"UNKNOWN:Error received from peer ipv4:172.217.29.74:443 {grpc_message:\"Publisher Model `projects/conteudo-autenticare/locations/us-central1/publishers/google/models/gemini-pro-vision` was not found or your project does not have access to it. Please ensure you are using a valid model version. For more information, see: https://cloud.google.com/vertex-ai/generative-ai/docs/learn/model-versions\", grpc_status:5}\"\n>\n\nThe above exception was the direct cause of the following exception:\n\nTraceback (most recent call last):\n  File \"/home/rafael/Desktop/projetos/yduqs_back/app/utils/verificaImagemVideo.py\", line 83, in analisar_imagem\n    response = model.generate_content([prompt, image])\n  File \"/home/rafael/.local/lib/python3.9/site-packages/vertexai/generative_models/_generative_models.py\", line 654, in generate_content\n    return self._generate_content(\n  File \"/home/rafael/.local/lib/python3.9/site-packages/vertexai/generative_models/_generative_models.py\", line 779, in _generate_content\n    gapic_response = self._prediction_client.generate_content(request=request)\n  File \"/home/rafael/.local/lib/python3.9/site-packages/google/cloud/aiplatform_v1/services/prediction_service/client.py\", line 2159, in generate_content\n    response = rpc(\n  File \"/home/rafael/.local/lib/python3.9/site-packages/google/api_core/gapic_v1/method.py\", line 131, in __call__\n    return wrapped_func(*args, **kwargs)\n  File \"/home/rafael/.local/lib/python3.9/site-packages/google/api_core/grpc_helpers.py\", line 78, in error_remapped_callable\n    raise exceptions.from_grpc_error(exc) from exc\ngoogle.api_core.exceptions.NotFound: 404 Publisher Model `projects/conteudo-autenticare/locations/us-central1/publishers/google/models/gemini-pro-vision` was not found or your project does not have access to it. Please ensure you are using a valid model version. For more information, see: https://cloud.google.com/vertex-ai/generative-ai/docs/learn/model-versions"}}
{"timestamp": "2025-05-16T02:05:17.284798", "level": "ERROR", "logger": "app.utils.verificaImagemVideo", "message": "Erro ao analisar imagem: 404 Publisher Model `projects/conteudo-autenticare/locations/us-central1/publishers/google/models/gemini-pro-vision` was not found or your project does not have access to it. Please ensure you are using a valid model version. For more information, see: https://cloud.google.com/vertex-ai/generative-ai/docs/learn/model-versions", "exception": {"type": "NotFound", "message": "404 Publisher Model `projects/conteudo-autenticare/locations/us-central1/publishers/google/models/gemini-pro-vision` was not found or your project does not have access to it. Please ensure you are using a valid model version. For more information, see: https://cloud.google.com/vertex-ai/generative-ai/docs/learn/model-versions", "traceback": "Traceback (most recent call last):\n  File \"/home/rafael/.local/lib/python3.9/site-packages/google/api_core/grpc_helpers.py\", line 76, in error_remapped_callable\n    return callable_(*args, **kwargs)\n  File \"/home/rafael/.local/lib/python3.9/site-packages/grpc/_channel.py\", line 1181, in __call__\n    return _end_unary_response_blocking(state, call, False, None)\n  File \"/home/rafael/.local/lib/python3.9/site-packages/grpc/_channel.py\", line 1006, in _end_unary_response_blocking\n    raise _InactiveRpcError(state)  # pytype: disable=not-instantiable\ngrpc._channel._InactiveRpcError: <_InactiveRpcError of RPC that terminated with:\n\tstatus = StatusCode.NOT_FOUND\n\tdetails = \"Publisher Model `projects/conteudo-autenticare/locations/us-central1/publishers/google/models/gemini-pro-vision` was not found or your project does not have access to it. Please ensure you are using a valid model version. For more information, see: https://cloud.google.com/vertex-ai/generative-ai/docs/learn/model-versions\"\n\tdebug_error_string = \"UNKNOWN:Error received from peer ipv4:142.250.219.234:443 {grpc_status:5, grpc_message:\"Publisher Model `projects/conteudo-autenticare/locations/us-central1/publishers/google/models/gemini-pro-vision` was not found or your project does not have access to it. Please ensure you are using a valid model version. For more information, see: https://cloud.google.com/vertex-ai/generative-ai/docs/learn/model-versions\"}\"\n>\n\nThe above exception was the direct cause of the following exception:\n\nTraceback (most recent call last):\n  File \"/home/rafael/Desktop/projetos/yduqs_back/app/utils/verificaImagemVideo.py\", line 83, in analisar_imagem\n    response = model.generate_content([prompt, image])\n  File \"/home/rafael/.local/lib/python3.9/site-packages/vertexai/generative_models/_generative_models.py\", line 654, in generate_content\n    return self._generate_content(\n  File \"/home/rafael/.local/lib/python3.9/site-packages/vertexai/generative_models/_generative_models.py\", line 779, in _generate_content\n    gapic_response = self._prediction_client.generate_content(request=request)\n  File \"/home/rafael/.local/lib/python3.9/site-packages/google/cloud/aiplatform_v1/services/prediction_service/client.py\", line 2159, in generate_content\n    response = rpc(\n  File \"/home/rafael/.local/lib/python3.9/site-packages/google/api_core/gapic_v1/method.py\", line 131, in __call__\n    return wrapped_func(*args, **kwargs)\n  File \"/home/rafael/.local/lib/python3.9/site-packages/google/api_core/grpc_helpers.py\", line 78, in error_remapped_callable\n    raise exceptions.from_grpc_error(exc) from exc\ngoogle.api_core.exceptions.NotFound: 404 Publisher Model `projects/conteudo-autenticare/locations/us-central1/publishers/google/models/gemini-pro-vision` was not found or your project does not have access to it. Please ensure you are using a valid model version. For more information, see: https://cloud.google.com/vertex-ai/generative-ai/docs/learn/model-versions"}}
{"timestamp": "2025-05-16T02:05:20.301980", "level": "ERROR", "logger": "app.utils.verificaImagemVideo", "message": "Erro ao analisar imagem: 404 Publisher Model `projects/conteudo-autenticare/locations/us-central1/publishers/google/models/gemini-pro-vision` was not found or your project does not have access to it. Please ensure you are using a valid model version. For more information, see: https://cloud.google.com/vertex-ai/generative-ai/docs/learn/model-versions", "exception": {"type": "NotFound", "message": "404 Publisher Model `projects/conteudo-autenticare/locations/us-central1/publishers/google/models/gemini-pro-vision` was not found or your project does not have access to it. Please ensure you are using a valid model version. For more information, see: https://cloud.google.com/vertex-ai/generative-ai/docs/learn/model-versions", "traceback": "Traceback (most recent call last):\n  File \"/home/rafael/.local/lib/python3.9/site-packages/google/api_core/grpc_helpers.py\", line 76, in error_remapped_callable\n    return callable_(*args, **kwargs)\n  File \"/home/rafael/.local/lib/python3.9/site-packages/grpc/_channel.py\", line 1181, in __call__\n    return _end_unary_response_blocking(state, call, False, None)\n  File \"/home/rafael/.local/lib/python3.9/site-packages/grpc/_channel.py\", line 1006, in _end_unary_response_blocking\n    raise _InactiveRpcError(state)  # pytype: disable=not-instantiable\ngrpc._channel._InactiveRpcError: <_InactiveRpcError of RPC that terminated with:\n\tstatus = StatusCode.NOT_FOUND\n\tdetails = \"Publisher Model `projects/conteudo-autenticare/locations/us-central1/publishers/google/models/gemini-pro-vision` was not found or your project does not have access to it. Please ensure you are using a valid model version. For more information, see: https://cloud.google.com/vertex-ai/generative-ai/docs/learn/model-versions\"\n\tdebug_error_string = \"UNKNOWN:Error received from peer ipv4:172.217.29.234:443 {grpc_status:5, grpc_message:\"Publisher Model `projects/conteudo-autenticare/locations/us-central1/publishers/google/models/gemini-pro-vision` was not found or your project does not have access to it. Please ensure you are using a valid model version. For more information, see: https://cloud.google.com/vertex-ai/generative-ai/docs/learn/model-versions\"}\"\n>\n\nThe above exception was the direct cause of the following exception:\n\nTraceback (most recent call last):\n  File \"/home/rafael/Desktop/projetos/yduqs_back/app/utils/verificaImagemVideo.py\", line 83, in analisar_imagem\n    response = model.generate_content([prompt, image])\n  File \"/home/rafael/.local/lib/python3.9/site-packages/vertexai/generative_models/_generative_models.py\", line 654, in generate_content\n    return self._generate_content(\n  File \"/home/rafael/.local/lib/python3.9/site-packages/vertexai/generative_models/_generative_models.py\", line 779, in _generate_content\n    gapic_response = self._prediction_client.generate_content(request=request)\n  File \"/home/rafael/.local/lib/python3.9/site-packages/google/cloud/aiplatform_v1/services/prediction_service/client.py\", line 2159, in generate_content\n    response = rpc(\n  File \"/home/rafael/.local/lib/python3.9/site-packages/google/api_core/gapic_v1/method.py\", line 131, in __call__\n    return wrapped_func(*args, **kwargs)\n  File \"/home/rafael/.local/lib/python3.9/site-packages/google/api_core/grpc_helpers.py\", line 78, in error_remapped_callable\n    raise exceptions.from_grpc_error(exc) from exc\ngoogle.api_core.exceptions.NotFound: 404 Publisher Model `projects/conteudo-autenticare/locations/us-central1/publishers/google/models/gemini-pro-vision` was not found or your project does not have access to it. Please ensure you are using a valid model version. For more information, see: https://cloud.google.com/vertex-ai/generative-ai/docs/learn/model-versions"}}
{"timestamp": "2025-05-16T02:05:23.671433", "level": "ERROR", "logger": "app.utils.verificaImagemVideo", "message": "Erro ao analisar imagem: 404 Publisher Model `projects/conteudo-autenticare/locations/us-central1/publishers/google/models/gemini-pro-vision` was not found or your project does not have access to it. Please ensure you are using a valid model version. For more information, see: https://cloud.google.com/vertex-ai/generative-ai/docs/learn/model-versions", "exception": {"type": "NotFound", "message": "404 Publisher Model `projects/conteudo-autenticare/locations/us-central1/publishers/google/models/gemini-pro-vision` was not found or your project does not have access to it. Please ensure you are using a valid model version. For more information, see: https://cloud.google.com/vertex-ai/generative-ai/docs/learn/model-versions", "traceback": "Traceback (most recent call last):\n  File \"/home/rafael/.local/lib/python3.9/site-packages/google/api_core/grpc_helpers.py\", line 76, in error_remapped_callable\n    return callable_(*args, **kwargs)\n  File \"/home/rafael/.local/lib/python3.9/site-packages/grpc/_channel.py\", line 1181, in __call__\n    return _end_unary_response_blocking(state, call, False, None)\n  File \"/home/rafael/.local/lib/python3.9/site-packages/grpc/_channel.py\", line 1006, in _end_unary_response_blocking\n    raise _InactiveRpcError(state)  # pytype: disable=not-instantiable\ngrpc._channel._InactiveRpcError: <_InactiveRpcError of RPC that terminated with:\n\tstatus = StatusCode.NOT_FOUND\n\tdetails = \"Publisher Model `projects/conteudo-autenticare/locations/us-central1/publishers/google/models/gemini-pro-vision` was not found or your project does not have access to it. Please ensure you are using a valid model version. For more information, see: https://cloud.google.com/vertex-ai/generative-ai/docs/learn/model-versions\"\n\tdebug_error_string = \"UNKNOWN:Error received from peer ipv4:142.251.135.202:443 {grpc_status:5, grpc_message:\"Publisher Model `projects/conteudo-autenticare/locations/us-central1/publishers/google/models/gemini-pro-vision` was not found or your project does not have access to it. Please ensure you are using a valid model version. For more information, see: https://cloud.google.com/vertex-ai/generative-ai/docs/learn/model-versions\"}\"\n>\n\nThe above exception was the direct cause of the following exception:\n\nTraceback (most recent call last):\n  File \"/home/rafael/Desktop/projetos/yduqs_back/app/utils/verificaImagemVideo.py\", line 83, in analisar_imagem\n    response = model.generate_content([prompt, image])\n  File \"/home/rafael/.local/lib/python3.9/site-packages/vertexai/generative_models/_generative_models.py\", line 654, in generate_content\n    return self._generate_content(\n  File \"/home/rafael/.local/lib/python3.9/site-packages/vertexai/generative_models/_generative_models.py\", line 779, in _generate_content\n    gapic_response = self._prediction_client.generate_content(request=request)\n  File \"/home/rafael/.local/lib/python3.9/site-packages/google/cloud/aiplatform_v1/services/prediction_service/client.py\", line 2159, in generate_content\n    response = rpc(\n  File \"/home/rafael/.local/lib/python3.9/site-packages/google/api_core/gapic_v1/method.py\", line 131, in __call__\n    return wrapped_func(*args, **kwargs)\n  File \"/home/rafael/.local/lib/python3.9/site-packages/google/api_core/grpc_helpers.py\", line 78, in error_remapped_callable\n    raise exceptions.from_grpc_error(exc) from exc\ngoogle.api_core.exceptions.NotFound: 404 Publisher Model `projects/conteudo-autenticare/locations/us-central1/publishers/google/models/gemini-pro-vision` was not found or your project does not have access to it. Please ensure you are using a valid model version. For more information, see: https://cloud.google.com/vertex-ai/generative-ai/docs/learn/model-versions"}}
{"timestamp": "2025-05-16T02:05:25.856075", "level": "ERROR", "logger": "app.utils.verificaImagemVideo", "message": "Erro ao analisar imagem: 404 Publisher Model `projects/conteudo-autenticare/locations/us-central1/publishers/google/models/gemini-pro-vision` was not found or your project does not have access to it. Please ensure you are using a valid model version. For more information, see: https://cloud.google.com/vertex-ai/generative-ai/docs/learn/model-versions", "exception": {"type": "NotFound", "message": "404 Publisher Model `projects/conteudo-autenticare/locations/us-central1/publishers/google/models/gemini-pro-vision` was not found or your project does not have access to it. Please ensure you are using a valid model version. For more information, see: https://cloud.google.com/vertex-ai/generative-ai/docs/learn/model-versions", "traceback": "Traceback (most recent call last):\n  File \"/home/rafael/.local/lib/python3.9/site-packages/google/api_core/grpc_helpers.py\", line 76, in error_remapped_callable\n    return callable_(*args, **kwargs)\n  File \"/home/rafael/.local/lib/python3.9/site-packages/grpc/_channel.py\", line 1181, in __call__\n    return _end_unary_response_blocking(state, call, False, None)\n  File \"/home/rafael/.local/lib/python3.9/site-packages/grpc/_channel.py\", line 1006, in _end_unary_response_blocking\n    raise _InactiveRpcError(state)  # pytype: disable=not-instantiable\ngrpc._channel._InactiveRpcError: <_InactiveRpcError of RPC that terminated with:\n\tstatus = StatusCode.NOT_FOUND\n\tdetails = \"Publisher Model `projects/conteudo-autenticare/locations/us-central1/publishers/google/models/gemini-pro-vision` was not found or your project does not have access to it. Please ensure you are using a valid model version. For more information, see: https://cloud.google.com/vertex-ai/generative-ai/docs/learn/model-versions\"\n\tdebug_error_string = \"UNKNOWN:Error received from peer ipv4:142.250.219.202:443 {grpc_message:\"Publisher Model `projects/conteudo-autenticare/locations/us-central1/publishers/google/models/gemini-pro-vision` was not found or your project does not have access to it. Please ensure you are using a valid model version. For more information, see: https://cloud.google.com/vertex-ai/generative-ai/docs/learn/model-versions\", grpc_status:5}\"\n>\n\nThe above exception was the direct cause of the following exception:\n\nTraceback (most recent call last):\n  File \"/home/rafael/Desktop/projetos/yduqs_back/app/utils/verificaImagemVideo.py\", line 83, in analisar_imagem\n    response = model.generate_content([prompt, image])\n  File \"/home/rafael/.local/lib/python3.9/site-packages/vertexai/generative_models/_generative_models.py\", line 654, in generate_content\n    return self._generate_content(\n  File \"/home/rafael/.local/lib/python3.9/site-packages/vertexai/generative_models/_generative_models.py\", line 779, in _generate_content\n    gapic_response = self._prediction_client.generate_content(request=request)\n  File \"/home/rafael/.local/lib/python3.9/site-packages/google/cloud/aiplatform_v1/services/prediction_service/client.py\", line 2159, in generate_content\n    response = rpc(\n  File \"/home/rafael/.local/lib/python3.9/site-packages/google/api_core/gapic_v1/method.py\", line 131, in __call__\n    return wrapped_func(*args, **kwargs)\n  File \"/home/rafael/.local/lib/python3.9/site-packages/google/api_core/grpc_helpers.py\", line 78, in error_remapped_callable\n    raise exceptions.from_grpc_error(exc) from exc\ngoogle.api_core.exceptions.NotFound: 404 Publisher Model `projects/conteudo-autenticare/locations/us-central1/publishers/google/models/gemini-pro-vision` was not found or your project does not have access to it. Please ensure you are using a valid model version. For more information, see: https://cloud.google.com/vertex-ai/generative-ai/docs/learn/model-versions"}}
{"timestamp": "2025-05-16T02:05:28.592469", "level": "ERROR", "logger": "app.utils.verificaImagemVideo", "message": "Erro ao analisar imagem: 404 Publisher Model `projects/conteudo-autenticare/locations/us-central1/publishers/google/models/gemini-pro-vision` was not found or your project does not have access to it. Please ensure you are using a valid model version. For more information, see: https://cloud.google.com/vertex-ai/generative-ai/docs/learn/model-versions", "exception": {"type": "NotFound", "message": "404 Publisher Model `projects/conteudo-autenticare/locations/us-central1/publishers/google/models/gemini-pro-vision` was not found or your project does not have access to it. Please ensure you are using a valid model version. For more information, see: https://cloud.google.com/vertex-ai/generative-ai/docs/learn/model-versions", "traceback": "Traceback (most recent call last):\n  File \"/home/rafael/.local/lib/python3.9/site-packages/google/api_core/grpc_helpers.py\", line 76, in error_remapped_callable\n    return callable_(*args, **kwargs)\n  File \"/home/rafael/.local/lib/python3.9/site-packages/grpc/_channel.py\", line 1181, in __call__\n    return _end_unary_response_blocking(state, call, False, None)\n  File \"/home/rafael/.local/lib/python3.9/site-packages/grpc/_channel.py\", line 1006, in _end_unary_response_blocking\n    raise _InactiveRpcError(state)  # pytype: disable=not-instantiable\ngrpc._channel._InactiveRpcError: <_InactiveRpcError of RPC that terminated with:\n\tstatus = StatusCode.NOT_FOUND\n\tdetails = \"Publisher Model `projects/conteudo-autenticare/locations/us-central1/publishers/google/models/gemini-pro-vision` was not found or your project does not have access to it. Please ensure you are using a valid model version. For more information, see: https://cloud.google.com/vertex-ai/generative-ai/docs/learn/model-versions\"\n\tdebug_error_string = \"UNKNOWN:Error received from peer ipv4:172.217.29.202:443 {grpc_status:5, grpc_message:\"Publisher Model `projects/conteudo-autenticare/locations/us-central1/publishers/google/models/gemini-pro-vision` was not found or your project does not have access to it. Please ensure you are using a valid model version. For more information, see: https://cloud.google.com/vertex-ai/generative-ai/docs/learn/model-versions\"}\"\n>\n\nThe above exception was the direct cause of the following exception:\n\nTraceback (most recent call last):\n  File \"/home/rafael/Desktop/projetos/yduqs_back/app/utils/verificaImagemVideo.py\", line 83, in analisar_imagem\n    response = model.generate_content([prompt, image])\n  File \"/home/rafael/.local/lib/python3.9/site-packages/vertexai/generative_models/_generative_models.py\", line 654, in generate_content\n    return self._generate_content(\n  File \"/home/rafael/.local/lib/python3.9/site-packages/vertexai/generative_models/_generative_models.py\", line 779, in _generate_content\n    gapic_response = self._prediction_client.generate_content(request=request)\n  File \"/home/rafael/.local/lib/python3.9/site-packages/google/cloud/aiplatform_v1/services/prediction_service/client.py\", line 2159, in generate_content\n    response = rpc(\n  File \"/home/rafael/.local/lib/python3.9/site-packages/google/api_core/gapic_v1/method.py\", line 131, in __call__\n    return wrapped_func(*args, **kwargs)\n  File \"/home/rafael/.local/lib/python3.9/site-packages/google/api_core/grpc_helpers.py\", line 78, in error_remapped_callable\n    raise exceptions.from_grpc_error(exc) from exc\ngoogle.api_core.exceptions.NotFound: 404 Publisher Model `projects/conteudo-autenticare/locations/us-central1/publishers/google/models/gemini-pro-vision` was not found or your project does not have access to it. Please ensure you are using a valid model version. For more information, see: https://cloud.google.com/vertex-ai/generative-ai/docs/learn/model-versions"}}
{"timestamp": "2025-05-16T02:05:30.510441", "level": "ERROR", "logger": "app.utils.verificaImagemVideo", "message": "Erro ao analisar imagem: 404 Publisher Model `projects/conteudo-autenticare/locations/us-central1/publishers/google/models/gemini-pro-vision` was not found or your project does not have access to it. Please ensure you are using a valid model version. For more information, see: https://cloud.google.com/vertex-ai/generative-ai/docs/learn/model-versions", "exception": {"type": "NotFound", "message": "404 Publisher Model `projects/conteudo-autenticare/locations/us-central1/publishers/google/models/gemini-pro-vision` was not found or your project does not have access to it. Please ensure you are using a valid model version. For more information, see: https://cloud.google.com/vertex-ai/generative-ai/docs/learn/model-versions", "traceback": "Traceback (most recent call last):\n  File \"/home/rafael/.local/lib/python3.9/site-packages/google/api_core/grpc_helpers.py\", line 76, in error_remapped_callable\n    return callable_(*args, **kwargs)\n  File \"/home/rafael/.local/lib/python3.9/site-packages/grpc/_channel.py\", line 1181, in __call__\n    return _end_unary_response_blocking(state, call, False, None)\n  File \"/home/rafael/.local/lib/python3.9/site-packages/grpc/_channel.py\", line 1006, in _end_unary_response_blocking\n    raise _InactiveRpcError(state)  # pytype: disable=not-instantiable\ngrpc._channel._InactiveRpcError: <_InactiveRpcError of RPC that terminated with:\n\tstatus = StatusCode.NOT_FOUND\n\tdetails = \"Publisher Model `projects/conteudo-autenticare/locations/us-central1/publishers/google/models/gemini-pro-vision` was not found or your project does not have access to it. Please ensure you are using a valid model version. For more information, see: https://cloud.google.com/vertex-ai/generative-ai/docs/learn/model-versions\"\n\tdebug_error_string = \"UNKNOWN:Error received from peer ipv4:142.250.78.106:443 {grpc_message:\"Publisher Model `projects/conteudo-autenticare/locations/us-central1/publishers/google/models/gemini-pro-vision` was not found or your project does not have access to it. Please ensure you are using a valid model version. For more information, see: https://cloud.google.com/vertex-ai/generative-ai/docs/learn/model-versions\", grpc_status:5}\"\n>\n\nThe above exception was the direct cause of the following exception:\n\nTraceback (most recent call last):\n  File \"/home/rafael/Desktop/projetos/yduqs_back/app/utils/verificaImagemVideo.py\", line 83, in analisar_imagem\n    response = model.generate_content([prompt, image])\n  File \"/home/rafael/.local/lib/python3.9/site-packages/vertexai/generative_models/_generative_models.py\", line 654, in generate_content\n    return self._generate_content(\n  File \"/home/rafael/.local/lib/python3.9/site-packages/vertexai/generative_models/_generative_models.py\", line 779, in _generate_content\n    gapic_response = self._prediction_client.generate_content(request=request)\n  File \"/home/rafael/.local/lib/python3.9/site-packages/google/cloud/aiplatform_v1/services/prediction_service/client.py\", line 2159, in generate_content\n    response = rpc(\n  File \"/home/rafael/.local/lib/python3.9/site-packages/google/api_core/gapic_v1/method.py\", line 131, in __call__\n    return wrapped_func(*args, **kwargs)\n  File \"/home/rafael/.local/lib/python3.9/site-packages/google/api_core/grpc_helpers.py\", line 78, in error_remapped_callable\n    raise exceptions.from_grpc_error(exc) from exc\ngoogle.api_core.exceptions.NotFound: 404 Publisher Model `projects/conteudo-autenticare/locations/us-central1/publishers/google/models/gemini-pro-vision` was not found or your project does not have access to it. Please ensure you are using a valid model version. For more information, see: https://cloud.google.com/vertex-ai/generative-ai/docs/learn/model-versions"}}
{"timestamp": "2025-05-16T02:11:04.045782", "level": "ERROR", "logger": "app.utils.verificaImagemVideo", "message": "Erro ao analisar imagem: N\u00e3o foi poss\u00edvel gerar an\u00e1lise da imagem com nenhum dos modelos dispon\u00edveis", "exception": {"type": "Exception", "message": "N\u00e3o foi poss\u00edvel gerar an\u00e1lise da imagem com nenhum dos modelos dispon\u00edveis", "traceback": "Traceback (most recent call last):\n  File \"/home/rafael/Desktop/projetos/yduqs_back/app/utils/verificaImagemVideo.py\", line 83, in analisar_imagem\n    raise Exception(\"N\u00e3o foi poss\u00edvel gerar an\u00e1lise da imagem com nenhum dos modelos dispon\u00edveis\")\nException: N\u00e3o foi poss\u00edvel gerar an\u00e1lise da imagem com nenhum dos modelos dispon\u00edveis"}}
{"timestamp": "2025-05-16T02:11:14.174744", "level": "ERROR", "logger": "app.utils.verificaImagemVideo", "message": "Erro ao analisar imagem: N\u00e3o foi poss\u00edvel gerar an\u00e1lise da imagem com nenhum dos modelos dispon\u00edveis", "exception": {"type": "Exception", "message": "N\u00e3o foi poss\u00edvel gerar an\u00e1lise da imagem com nenhum dos modelos dispon\u00edveis", "traceback": "Traceback (most recent call last):\n  File \"/home/rafael/Desktop/projetos/yduqs_back/app/utils/verificaImagemVideo.py\", line 83, in analisar_imagem\n    raise Exception(\"N\u00e3o foi poss\u00edvel gerar an\u00e1lise da imagem com nenhum dos modelos dispon\u00edveis\")\nException: N\u00e3o foi poss\u00edvel gerar an\u00e1lise da imagem com nenhum dos modelos dispon\u00edveis"}}
{"timestamp": "2025-05-16T02:11:23.667789", "level": "ERROR", "logger": "app.utils.verificaImagemVideo", "message": "Erro ao analisar imagem: N\u00e3o foi poss\u00edvel gerar an\u00e1lise da imagem com nenhum dos modelos dispon\u00edveis", "exception": {"type": "Exception", "message": "N\u00e3o foi poss\u00edvel gerar an\u00e1lise da imagem com nenhum dos modelos dispon\u00edveis", "traceback": "Traceback (most recent call last):\n  File \"/home/rafael/Desktop/projetos/yduqs_back/app/utils/verificaImagemVideo.py\", line 83, in analisar_imagem\n    raise Exception(\"N\u00e3o foi poss\u00edvel gerar an\u00e1lise da imagem com nenhum dos modelos dispon\u00edveis\")\nException: N\u00e3o foi poss\u00edvel gerar an\u00e1lise da imagem com nenhum dos modelos dispon\u00edveis"}}
{"timestamp": "2025-05-16T02:11:32.845725", "level": "ERROR", "logger": "app.utils.verificaImagemVideo", "message": "Erro ao analisar imagem: N\u00e3o foi poss\u00edvel gerar an\u00e1lise da imagem com nenhum dos modelos dispon\u00edveis", "exception": {"type": "Exception", "message": "N\u00e3o foi poss\u00edvel gerar an\u00e1lise da imagem com nenhum dos modelos dispon\u00edveis", "traceback": "Traceback (most recent call last):\n  File \"/home/rafael/Desktop/projetos/yduqs_back/app/utils/verificaImagemVideo.py\", line 83, in analisar_imagem\n    raise Exception(\"N\u00e3o foi poss\u00edvel gerar an\u00e1lise da imagem com nenhum dos modelos dispon\u00edveis\")\nException: N\u00e3o foi poss\u00edvel gerar an\u00e1lise da imagem com nenhum dos modelos dispon\u00edveis"}}
{"timestamp": "2025-05-16T02:15:21.131648", "level": "ERROR", "logger": "app.utils.verificaImagemVideo", "message": "Erro ao analisar imagem: could not convert string to float: '0 (Confian\u00e7a de que a entrada fornecida \u2013 que n\u00e3o \u00e9 uma imagem \u2013 corresponda \u00e0 descri\u00e7\u00e3o \"Favela soccer passion\".)'", "exception": {"type": "ValueError", "message": "could not convert string to float: '0 (Confian\u00e7a de que a entrada fornecida \u2013 que n\u00e3o \u00e9 uma imagem \u2013 corresponda \u00e0 descri\u00e7\u00e3o \"Favela soccer passion\".)'", "traceback": "Traceback (most recent call last):\n  File \"/home/rafael/Desktop/projetos/yduqs_back/app/utils/verificaImagemVideo.py\", line 100, in analisar_imagem\n    confianca = float(linha.replace('CONFIAN\u00c7A:', '').strip().replace('%', '')) / 100\nValueError: could not convert string to float: '0 (Confian\u00e7a de que a entrada fornecida \u2013 que n\u00e3o \u00e9 uma imagem \u2013 corresponda \u00e0 descri\u00e7\u00e3o \"Favela soccer passion\".)'"}}
{"timestamp": "2025-05-16T02:18:16.106708", "level": "ERROR", "logger": "app.utils.verificaImagemVideo", "message": "Erro ao analisar imagem: could not convert string to float: '100 (para a descri\u00e7\u00e3o \"Favela football game\")'", "exception": {"type": "ValueError", "message": "could not convert string to float: '100 (para a descri\u00e7\u00e3o \"Favela football game\")'", "traceback": "Traceback (most recent call last):\n  File \"/home/rafael/Desktop/projetos/yduqs_back/app/utils/verificaImagemVideo.py\", line 100, in analisar_imagem\n    confianca = float(linha.replace('CONFIAN\u00c7A:', '').strip().replace('%', '')) / 100\nValueError: could not convert string to float: '100 (para a descri\u00e7\u00e3o \"Favela football game\")'"}}
{"timestamp": "2025-05-16T02:20:34.847941", "level": "ERROR", "logger": "app.utils.verificaImagemVideo", "message": "Erro ao analisar imagem: N\u00e3o foi poss\u00edvel gerar an\u00e1lise da imagem com nenhum dos modelos dispon\u00edveis", "exception": {"type": "Exception", "message": "N\u00e3o foi poss\u00edvel gerar an\u00e1lise da imagem com nenhum dos modelos dispon\u00edveis", "traceback": "Traceback (most recent call last):\n  File \"/home/rafael/Desktop/projetos/yduqs_back/app/utils/verificaImagemVideo.py\", line 83, in analisar_imagem\n    raise Exception(\"N\u00e3o foi poss\u00edvel gerar an\u00e1lise da imagem com nenhum dos modelos dispon\u00edveis\")\nException: N\u00e3o foi poss\u00edvel gerar an\u00e1lise da imagem com nenhum dos modelos dispon\u00edveis"}}
{"timestamp": "2025-05-16T02:24:07.052982", "level": "ERROR", "logger": "app.utils.verificaImagemVideo", "message": "Erro ao analisar imagem: N\u00e3o foi poss\u00edvel gerar an\u00e1lise da imagem com nenhum dos modelos dispon\u00edveis", "exception": {"type": "Exception", "message": "N\u00e3o foi poss\u00edvel gerar an\u00e1lise da imagem com nenhum dos modelos dispon\u00edveis", "traceback": "Traceback (most recent call last):\n  File \"/home/rafael/Desktop/projetos/yduqs_back/app/utils/verificaImagemVideo.py\", line 83, in analisar_imagem\n    raise Exception(\"N\u00e3o foi poss\u00edvel gerar an\u00e1lise da imagem com nenhum dos modelos dispon\u00edveis\")\nException: N\u00e3o foi poss\u00edvel gerar an\u00e1lise da imagem com nenhum dos modelos dispon\u00edveis"}}
{"timestamp": "2025-05-16T02:24:08.181437", "level": "ERROR", "logger": "app.utils.verificaImagemVideo", "message": "Erro ao analisar imagem: N\u00e3o foi poss\u00edvel gerar an\u00e1lise da imagem com nenhum dos modelos dispon\u00edveis", "exception": {"type": "Exception", "message": "N\u00e3o foi poss\u00edvel gerar an\u00e1lise da imagem com nenhum dos modelos dispon\u00edveis", "traceback": "Traceback (most recent call last):\n  File \"/home/rafael/Desktop/projetos/yduqs_back/app/utils/verificaImagemVideo.py\", line 83, in analisar_imagem\n    raise Exception(\"N\u00e3o foi poss\u00edvel gerar an\u00e1lise da imagem com nenhum dos modelos dispon\u00edveis\")\nException: N\u00e3o foi poss\u00edvel gerar an\u00e1lise da imagem com nenhum dos modelos dispon\u00edveis"}}
{"timestamp": "2025-05-16T02:24:09.038503", "level": "ERROR", "logger": "app.utils.verificaImagemVideo", "message": "Erro ao analisar imagem: N\u00e3o foi poss\u00edvel gerar an\u00e1lise da imagem com nenhum dos modelos dispon\u00edveis", "exception": {"type": "Exception", "message": "N\u00e3o foi poss\u00edvel gerar an\u00e1lise da imagem com nenhum dos modelos dispon\u00edveis", "traceback": "Traceback (most recent call last):\n  File \"/home/rafael/Desktop/projetos/yduqs_back/app/utils/verificaImagemVideo.py\", line 83, in analisar_imagem\n    raise Exception(\"N\u00e3o foi poss\u00edvel gerar an\u00e1lise da imagem com nenhum dos modelos dispon\u00edveis\")\nException: N\u00e3o foi poss\u00edvel gerar an\u00e1lise da imagem com nenhum dos modelos dispon\u00edveis"}}
{"timestamp": "2025-05-16T02:24:09.463864", "level": "ERROR", "logger": "app.utils.verificaImagemVideo", "message": "Erro ao analisar imagem: N\u00e3o foi poss\u00edvel gerar an\u00e1lise da imagem com nenhum dos modelos dispon\u00edveis", "exception": {"type": "Exception", "message": "N\u00e3o foi poss\u00edvel gerar an\u00e1lise da imagem com nenhum dos modelos dispon\u00edveis", "traceback": "Traceback (most recent call last):\n  File \"/home/rafael/Desktop/projetos/yduqs_back/app/utils/verificaImagemVideo.py\", line 83, in analisar_imagem\n    raise Exception(\"N\u00e3o foi poss\u00edvel gerar an\u00e1lise da imagem com nenhum dos modelos dispon\u00edveis\")\nException: N\u00e3o foi poss\u00edvel gerar an\u00e1lise da imagem com nenhum dos modelos dispon\u00edveis"}}
{"timestamp": "2025-05-16T02:24:10.287564", "level": "ERROR", "logger": "app.utils.verificaImagemVideo", "message": "Erro ao analisar imagem: N\u00e3o foi poss\u00edvel gerar an\u00e1lise da imagem com nenhum dos modelos dispon\u00edveis", "exception": {"type": "Exception", "message": "N\u00e3o foi poss\u00edvel gerar an\u00e1lise da imagem com nenhum dos modelos dispon\u00edveis", "traceback": "Traceback (most recent call last):\n  File \"/home/rafael/Desktop/projetos/yduqs_back/app/utils/verificaImagemVideo.py\", line 83, in analisar_imagem\n    raise Exception(\"N\u00e3o foi poss\u00edvel gerar an\u00e1lise da imagem com nenhum dos modelos dispon\u00edveis\")\nException: N\u00e3o foi poss\u00edvel gerar an\u00e1lise da imagem com nenhum dos modelos dispon\u00edveis"}}
{"timestamp": "2025-05-16T02:24:11.094059", "level": "ERROR", "logger": "app.utils.verificaImagemVideo", "message": "Erro ao analisar imagem: N\u00e3o foi poss\u00edvel gerar an\u00e1lise da imagem com nenhum dos modelos dispon\u00edveis", "exception": {"type": "Exception", "message": "N\u00e3o foi poss\u00edvel gerar an\u00e1lise da imagem com nenhum dos modelos dispon\u00edveis", "traceback": "Traceback (most recent call last):\n  File \"/home/rafael/Desktop/projetos/yduqs_back/app/utils/verificaImagemVideo.py\", line 83, in analisar_imagem\n    raise Exception(\"N\u00e3o foi poss\u00edvel gerar an\u00e1lise da imagem com nenhum dos modelos dispon\u00edveis\")\nException: N\u00e3o foi poss\u00edvel gerar an\u00e1lise da imagem com nenhum dos modelos dispon\u00edveis"}}
{"timestamp": "2025-05-16T02:24:11.653914", "level": "ERROR", "logger": "app.utils.verificaImagemVideo", "message": "Erro ao analisar imagem: N\u00e3o foi poss\u00edvel gerar an\u00e1lise da imagem com nenhum dos modelos dispon\u00edveis", "exception": {"type": "Exception", "message": "N\u00e3o foi poss\u00edvel gerar an\u00e1lise da imagem com nenhum dos modelos dispon\u00edveis", "traceback": "Traceback (most recent call last):\n  File \"/home/rafael/Desktop/projetos/yduqs_back/app/utils/verificaImagemVideo.py\", line 83, in analisar_imagem\n    raise Exception(\"N\u00e3o foi poss\u00edvel gerar an\u00e1lise da imagem com nenhum dos modelos dispon\u00edveis\")\nException: N\u00e3o foi poss\u00edvel gerar an\u00e1lise da imagem com nenhum dos modelos dispon\u00edveis"}}
{"timestamp": "2025-05-16T02:24:11.900900", "level": "ERROR", "logger": "app.utils.verificaImagemVideo", "message": "Erro ao analisar imagem: N\u00e3o foi poss\u00edvel gerar an\u00e1lise da imagem com nenhum dos modelos dispon\u00edveis", "exception": {"type": "Exception", "message": "N\u00e3o foi poss\u00edvel gerar an\u00e1lise da imagem com nenhum dos modelos dispon\u00edveis", "traceback": "Traceback (most recent call last):\n  File \"/home/rafael/Desktop/projetos/yduqs_back/app/utils/verificaImagemVideo.py\", line 83, in analisar_imagem\n    raise Exception(\"N\u00e3o foi poss\u00edvel gerar an\u00e1lise da imagem com nenhum dos modelos dispon\u00edveis\")\nException: N\u00e3o foi poss\u00edvel gerar an\u00e1lise da imagem com nenhum dos modelos dispon\u00edveis"}}
{"timestamp": "2025-05-16T02:24:12.091832", "level": "ERROR", "logger": "app.utils.verificaImagemVideo", "message": "Erro ao analisar imagem: N\u00e3o foi poss\u00edvel gerar an\u00e1lise da imagem com nenhum dos modelos dispon\u00edveis", "exception": {"type": "Exception", "message": "N\u00e3o foi poss\u00edvel gerar an\u00e1lise da imagem com nenhum dos modelos dispon\u00edveis", "traceback": "Traceback (most recent call last):\n  File \"/home/rafael/Desktop/projetos/yduqs_back/app/utils/verificaImagemVideo.py\", line 83, in analisar_imagem\n    raise Exception(\"N\u00e3o foi poss\u00edvel gerar an\u00e1lise da imagem com nenhum dos modelos dispon\u00edveis\")\nException: N\u00e3o foi poss\u00edvel gerar an\u00e1lise da imagem com nenhum dos modelos dispon\u00edveis"}}
{"timestamp": "2025-05-16T02:24:12.332341", "level": "ERROR", "logger": "app.utils.verificaImagemVideo", "message": "Erro ao analisar imagem: N\u00e3o foi poss\u00edvel gerar an\u00e1lise da imagem com nenhum dos modelos dispon\u00edveis", "exception": {"type": "Exception", "message": "N\u00e3o foi poss\u00edvel gerar an\u00e1lise da imagem com nenhum dos modelos dispon\u00edveis", "traceback": "Traceback (most recent call last):\n  File \"/home/rafael/Desktop/projetos/yduqs_back/app/utils/verificaImagemVideo.py\", line 83, in analisar_imagem\n    raise Exception(\"N\u00e3o foi poss\u00edvel gerar an\u00e1lise da imagem com nenhum dos modelos dispon\u00edveis\")\nException: N\u00e3o foi poss\u00edvel gerar an\u00e1lise da imagem com nenhum dos modelos dispon\u00edveis"}}
{"timestamp": "2025-05-16T02:24:12.948843", "level": "ERROR", "logger": "app.utils.verificaImagemVideo", "message": "Erro ao analisar imagem: N\u00e3o foi poss\u00edvel gerar an\u00e1lise da imagem com nenhum dos modelos dispon\u00edveis", "exception": {"type": "Exception", "message": "N\u00e3o foi poss\u00edvel gerar an\u00e1lise da imagem com nenhum dos modelos dispon\u00edveis", "traceback": "Traceback (most recent call last):\n  File \"/home/rafael/Desktop/projetos/yduqs_back/app/utils/verificaImagemVideo.py\", line 83, in analisar_imagem\n    raise Exception(\"N\u00e3o foi poss\u00edvel gerar an\u00e1lise da imagem com nenhum dos modelos dispon\u00edveis\")\nException: N\u00e3o foi poss\u00edvel gerar an\u00e1lise da imagem com nenhum dos modelos dispon\u00edveis"}}
{"timestamp": "2025-05-16T02:24:13.399888", "level": "ERROR", "logger": "app.utils.verificaImagemVideo", "message": "Erro ao analisar imagem: N\u00e3o foi poss\u00edvel gerar an\u00e1lise da imagem com nenhum dos modelos dispon\u00edveis", "exception": {"type": "Exception", "message": "N\u00e3o foi poss\u00edvel gerar an\u00e1lise da imagem com nenhum dos modelos dispon\u00edveis", "traceback": "Traceback (most recent call last):\n  File \"/home/rafael/Desktop/projetos/yduqs_back/app/utils/verificaImagemVideo.py\", line 83, in analisar_imagem\n    raise Exception(\"N\u00e3o foi poss\u00edvel gerar an\u00e1lise da imagem com nenhum dos modelos dispon\u00edveis\")\nException: N\u00e3o foi poss\u00edvel gerar an\u00e1lise da imagem com nenhum dos modelos dispon\u00edveis"}}
{"timestamp": "2025-05-16T02:24:13.840756", "level": "ERROR", "logger": "app.utils.verificaImagemVideo", "message": "Erro ao analisar imagem: N\u00e3o foi poss\u00edvel gerar an\u00e1lise da imagem com nenhum dos modelos dispon\u00edveis", "exception": {"type": "Exception", "message": "N\u00e3o foi poss\u00edvel gerar an\u00e1lise da imagem com nenhum dos modelos dispon\u00edveis", "traceback": "Traceback (most recent call last):\n  File \"/home/rafael/Desktop/projetos/yduqs_back/app/utils/verificaImagemVideo.py\", line 83, in analisar_imagem\n    raise Exception(\"N\u00e3o foi poss\u00edvel gerar an\u00e1lise da imagem com nenhum dos modelos dispon\u00edveis\")\nException: N\u00e3o foi poss\u00edvel gerar an\u00e1lise da imagem com nenhum dos modelos dispon\u00edveis"}}
{"timestamp": "2025-05-16T02:24:14.327018", "level": "ERROR", "logger": "app.utils.verificaImagemVideo", "message": "Erro ao analisar imagem: N\u00e3o foi poss\u00edvel gerar an\u00e1lise da imagem com nenhum dos modelos dispon\u00edveis", "exception": {"type": "Exception", "message": "N\u00e3o foi poss\u00edvel gerar an\u00e1lise da imagem com nenhum dos modelos dispon\u00edveis", "traceback": "Traceback (most recent call last):\n  File \"/home/rafael/Desktop/projetos/yduqs_back/app/utils/verificaImagemVideo.py\", line 83, in analisar_imagem\n    raise Exception(\"N\u00e3o foi poss\u00edvel gerar an\u00e1lise da imagem com nenhum dos modelos dispon\u00edveis\")\nException: N\u00e3o foi poss\u00edvel gerar an\u00e1lise da imagem com nenhum dos modelos dispon\u00edveis"}}
{"timestamp": "2025-05-16T02:24:15.070168", "level": "ERROR", "logger": "app.utils.verificaImagemVideo", "message": "Erro ao analisar imagem: N\u00e3o foi poss\u00edvel gerar an\u00e1lise da imagem com nenhum dos modelos dispon\u00edveis", "exception": {"type": "Exception", "message": "N\u00e3o foi poss\u00edvel gerar an\u00e1lise da imagem com nenhum dos modelos dispon\u00edveis", "traceback": "Traceback (most recent call last):\n  File \"/home/rafael/Desktop/projetos/yduqs_back/app/utils/verificaImagemVideo.py\", line 83, in analisar_imagem\n    raise Exception(\"N\u00e3o foi poss\u00edvel gerar an\u00e1lise da imagem com nenhum dos modelos dispon\u00edveis\")\nException: N\u00e3o foi poss\u00edvel gerar an\u00e1lise da imagem com nenhum dos modelos dispon\u00edveis"}}
{"timestamp": "2025-05-16T02:56:53.879893", "level": "ERROR", "logger": "app.utils.verificaImagemVideo", "message": "Gemini n\u00e3o retornou an\u00e1lise"}
{"timestamp": "2025-05-16T02:56:54.997669", "level": "ERROR", "logger": "app.utils.verificaImagemVideo", "message": "Gemini n\u00e3o retornou an\u00e1lise"}
{"timestamp": "2025-05-16T02:56:56.068246", "level": "ERROR", "logger": "app.utils.verificaImagemVideo", "message": "Gemini n\u00e3o retornou an\u00e1lise"}
{"timestamp": "2025-05-16T02:56:57.237816", "level": "ERROR", "logger": "app.utils.verificaImagemVideo", "message": "Gemini n\u00e3o retornou an\u00e1lise"}
{"timestamp": "2025-05-16T02:56:58.083856", "level": "ERROR", "logger": "app.utils.verificaImagemVideo", "message": "Gemini n\u00e3o retornou an\u00e1lise"}
{"timestamp": "2025-05-16T02:56:59.408585", "level": "ERROR", "logger": "app.utils.verificaImagemVideo", "message": "Gemini n\u00e3o retornou an\u00e1lise"}
{"timestamp": "2025-05-16T02:57:00.555458", "level": "ERROR", "logger": "app.utils.verificaImagemVideo", "message": "Gemini n\u00e3o retornou an\u00e1lise"}
{"timestamp": "2025-05-16T02:57:01.782902", "level": "ERROR", "logger": "app.utils.verificaImagemVideo", "message": "Gemini n\u00e3o retornou an\u00e1lise"}
{"timestamp": "2025-05-16T02:57:02.435324", "level": "ERROR", "logger": "app.utils.verificaImagemVideo", "message": "Gemini n\u00e3o retornou an\u00e1lise"}
{"timestamp": "2025-05-16T02:57:03.271156", "level": "ERROR", "logger": "app.utils.verificaImagemVideo", "message": "Gemini n\u00e3o retornou an\u00e1lise"}
{"timestamp": "2025-05-16T02:57:05.666389", "level": "ERROR", "logger": "app.utils.verificaImagemVideo", "message": "Gemini n\u00e3o retornou an\u00e1lise"}
{"timestamp": "2025-05-16T02:57:05.964525", "level": "ERROR", "logger": "app.utils.verificaImagemVideo", "message": "Gemini n\u00e3o retornou an\u00e1lise"}
{"timestamp": "2025-05-16T02:57:09.116945", "level": "ERROR", "logger": "app.utils.verificaImagemVideo", "message": "Gemini n\u00e3o retornou an\u00e1lise"}
{"timestamp": "2025-05-16T02:57:13.175082", "level": "ERROR", "logger": "app.utils.verificaImagemVideo", "message": "Gemini n\u00e3o retornou an\u00e1lise"}
{"timestamp": "2025-05-16T02:57:13.672259", "level": "ERROR", "logger": "app.utils.verificaImagemVideo", "message": "Gemini n\u00e3o retornou an\u00e1lise"}
{"timestamp": "2025-05-16T03:14:48.232944", "level": "ERROR", "logger": "app.utils.verificaImagemVideo", "message": "Erro ao analisar imagem: 404 Publisher Model `projects/conteudo-autenticare/locations/us-central1/publishers/google/models/gemini-pro-vision` was not found or your project does not have access to it. Please ensure you are using a valid model version. For more information, see: https://cloud.google.com/vertex-ai/generative-ai/docs/learn/model-versions", "exception": {"type": "NotFound", "message": "404 Publisher Model `projects/conteudo-autenticare/locations/us-central1/publishers/google/models/gemini-pro-vision` was not found or your project does not have access to it. Please ensure you are using a valid model version. For more information, see: https://cloud.google.com/vertex-ai/generative-ai/docs/learn/model-versions", "traceback": "Traceback (most recent call last):\n  File \"/home/rafael/.local/lib/python3.9/site-packages/google/api_core/grpc_helpers.py\", line 76, in error_remapped_callable\n    return callable_(*args, **kwargs)\n  File \"/home/rafael/.local/lib/python3.9/site-packages/grpc/_channel.py\", line 1181, in __call__\n    return _end_unary_response_blocking(state, call, False, None)\n  File \"/home/rafael/.local/lib/python3.9/site-packages/grpc/_channel.py\", line 1006, in _end_unary_response_blocking\n    raise _InactiveRpcError(state)  # pytype: disable=not-instantiable\ngrpc._channel._InactiveRpcError: <_InactiveRpcError of RPC that terminated with:\n\tstatus = StatusCode.NOT_FOUND\n\tdetails = \"Publisher Model `projects/conteudo-autenticare/locations/us-central1/publishers/google/models/gemini-pro-vision` was not found or your project does not have access to it. Please ensure you are using a valid model version. For more information, see: https://cloud.google.com/vertex-ai/generative-ai/docs/learn/model-versions\"\n\tdebug_error_string = \"UNKNOWN:Error received from peer ipv4:142.250.219.234:443 {grpc_message:\"Publisher Model `projects/conteudo-autenticare/locations/us-central1/publishers/google/models/gemini-pro-vision` was not found or your project does not have access to it. Please ensure you are using a valid model version. For more information, see: https://cloud.google.com/vertex-ai/generative-ai/docs/learn/model-versions\", grpc_status:5}\"\n>\n\nThe above exception was the direct cause of the following exception:\n\nTraceback (most recent call last):\n  File \"/home/rafael/Desktop/projetos/yduqs_back/app/utils/verificaImagemVideo.py\", line 83, in analisar_imagem\n    response = model.generate_content([prompt, image])\n  File \"/home/rafael/.local/lib/python3.9/site-packages/vertexai/generative_models/_generative_models.py\", line 654, in generate_content\n    return self._generate_content(\n  File \"/home/rafael/.local/lib/python3.9/site-packages/vertexai/generative_models/_generative_models.py\", line 779, in _generate_content\n    gapic_response = self._prediction_client.generate_content(request=request)\n  File \"/home/rafael/.local/lib/python3.9/site-packages/google/cloud/aiplatform_v1/services/prediction_service/client.py\", line 2159, in generate_content\n    response = rpc(\n  File \"/home/rafael/.local/lib/python3.9/site-packages/google/api_core/gapic_v1/method.py\", line 131, in __call__\n    return wrapped_func(*args, **kwargs)\n  File \"/home/rafael/.local/lib/python3.9/site-packages/google/api_core/grpc_helpers.py\", line 78, in error_remapped_callable\n    raise exceptions.from_grpc_error(exc) from exc\ngoogle.api_core.exceptions.NotFound: 404 Publisher Model `projects/conteudo-autenticare/locations/us-central1/publishers/google/models/gemini-pro-vision` was not found or your project does not have access to it. Please ensure you are using a valid model version. For more information, see: https://cloud.google.com/vertex-ai/generative-ai/docs/learn/model-versions"}}
{"timestamp": "2025-05-16T03:14:49.959405", "level": "ERROR", "logger": "app.utils.verificaImagemVideo", "message": "Erro ao analisar imagem: 404 Publisher Model `projects/conteudo-autenticare/locations/us-central1/publishers/google/models/gemini-pro-vision` was not found or your project does not have access to it. Please ensure you are using a valid model version. For more information, see: https://cloud.google.com/vertex-ai/generative-ai/docs/learn/model-versions", "exception": {"type": "NotFound", "message": "404 Publisher Model `projects/conteudo-autenticare/locations/us-central1/publishers/google/models/gemini-pro-vision` was not found or your project does not have access to it. Please ensure you are using a valid model version. For more information, see: https://cloud.google.com/vertex-ai/generative-ai/docs/learn/model-versions", "traceback": "Traceback (most recent call last):\n  File \"/home/rafael/.local/lib/python3.9/site-packages/google/api_core/grpc_helpers.py\", line 76, in error_remapped_callable\n    return callable_(*args, **kwargs)\n  File \"/home/rafael/.local/lib/python3.9/site-packages/grpc/_channel.py\", line 1181, in __call__\n    return _end_unary_response_blocking(state, call, False, None)\n  File \"/home/rafael/.local/lib/python3.9/site-packages/grpc/_channel.py\", line 1006, in _end_unary_response_blocking\n    raise _InactiveRpcError(state)  # pytype: disable=not-instantiable\ngrpc._channel._InactiveRpcError: <_InactiveRpcError of RPC that terminated with:\n\tstatus = StatusCode.NOT_FOUND\n\tdetails = \"Publisher Model `projects/conteudo-autenticare/locations/us-central1/publishers/google/models/gemini-pro-vision` was not found or your project does not have access to it. Please ensure you are using a valid model version. For more information, see: https://cloud.google.com/vertex-ai/generative-ai/docs/learn/model-versions\"\n\tdebug_error_string = \"UNKNOWN:Error received from peer ipv4:172.217.28.170:443 {grpc_message:\"Publisher Model `projects/conteudo-autenticare/locations/us-central1/publishers/google/models/gemini-pro-vision` was not found or your project does not have access to it. Please ensure you are using a valid model version. For more information, see: https://cloud.google.com/vertex-ai/generative-ai/docs/learn/model-versions\", grpc_status:5}\"\n>\n\nThe above exception was the direct cause of the following exception:\n\nTraceback (most recent call last):\n  File \"/home/rafael/Desktop/projetos/yduqs_back/app/utils/verificaImagemVideo.py\", line 83, in analisar_imagem\n    response = model.generate_content([prompt, image])\n  File \"/home/rafael/.local/lib/python3.9/site-packages/vertexai/generative_models/_generative_models.py\", line 654, in generate_content\n    return self._generate_content(\n  File \"/home/rafael/.local/lib/python3.9/site-packages/vertexai/generative_models/_generative_models.py\", line 779, in _generate_content\n    gapic_response = self._prediction_client.generate_content(request=request)\n  File \"/home/rafael/.local/lib/python3.9/site-packages/google/cloud/aiplatform_v1/services/prediction_service/client.py\", line 2159, in generate_content\n    response = rpc(\n  File \"/home/rafael/.local/lib/python3.9/site-packages/google/api_core/gapic_v1/method.py\", line 131, in __call__\n    return wrapped_func(*args, **kwargs)\n  File \"/home/rafael/.local/lib/python3.9/site-packages/google/api_core/grpc_helpers.py\", line 78, in error_remapped_callable\n    raise exceptions.from_grpc_error(exc) from exc\ngoogle.api_core.exceptions.NotFound: 404 Publisher Model `projects/conteudo-autenticare/locations/us-central1/publishers/google/models/gemini-pro-vision` was not found or your project does not have access to it. Please ensure you are using a valid model version. For more information, see: https://cloud.google.com/vertex-ai/generative-ai/docs/learn/model-versions"}}
{"timestamp": "2025-05-16T03:14:51.833298", "level": "ERROR", "logger": "app.utils.verificaImagemVideo", "message": "Erro ao analisar imagem: 404 Publisher Model `projects/conteudo-autenticare/locations/us-central1/publishers/google/models/gemini-pro-vision` was not found or your project does not have access to it. Please ensure you are using a valid model version. For more information, see: https://cloud.google.com/vertex-ai/generative-ai/docs/learn/model-versions", "exception": {"type": "NotFound", "message": "404 Publisher Model `projects/conteudo-autenticare/locations/us-central1/publishers/google/models/gemini-pro-vision` was not found or your project does not have access to it. Please ensure you are using a valid model version. For more information, see: https://cloud.google.com/vertex-ai/generative-ai/docs/learn/model-versions", "traceback": "Traceback (most recent call last):\n  File \"/home/rafael/.local/lib/python3.9/site-packages/google/api_core/grpc_helpers.py\", line 76, in error_remapped_callable\n    return callable_(*args, **kwargs)\n  File \"/home/rafael/.local/lib/python3.9/site-packages/grpc/_channel.py\", line 1181, in __call__\n    return _end_unary_response_blocking(state, call, False, None)\n  File \"/home/rafael/.local/lib/python3.9/site-packages/grpc/_channel.py\", line 1006, in _end_unary_response_blocking\n    raise _InactiveRpcError(state)  # pytype: disable=not-instantiable\ngrpc._channel._InactiveRpcError: <_InactiveRpcError of RPC that terminated with:\n\tstatus = StatusCode.NOT_FOUND\n\tdetails = \"Publisher Model `projects/conteudo-autenticare/locations/us-central1/publishers/google/models/gemini-pro-vision` was not found or your project does not have access to it. Please ensure you are using a valid model version. For more information, see: https://cloud.google.com/vertex-ai/generative-ai/docs/learn/model-versions\"\n\tdebug_error_string = \"UNKNOWN:Error received from peer ipv4:172.217.172.42:443 {grpc_message:\"Publisher Model `projects/conteudo-autenticare/locations/us-central1/publishers/google/models/gemini-pro-vision` was not found or your project does not have access to it. Please ensure you are using a valid model version. For more information, see: https://cloud.google.com/vertex-ai/generative-ai/docs/learn/model-versions\", grpc_status:5}\"\n>\n\nThe above exception was the direct cause of the following exception:\n\nTraceback (most recent call last):\n  File \"/home/rafael/Desktop/projetos/yduqs_back/app/utils/verificaImagemVideo.py\", line 83, in analisar_imagem\n    response = model.generate_content([prompt, image])\n  File \"/home/rafael/.local/lib/python3.9/site-packages/vertexai/generative_models/_generative_models.py\", line 654, in generate_content\n    return self._generate_content(\n  File \"/home/rafael/.local/lib/python3.9/site-packages/vertexai/generative_models/_generative_models.py\", line 779, in _generate_content\n    gapic_response = self._prediction_client.generate_content(request=request)\n  File \"/home/rafael/.local/lib/python3.9/site-packages/google/cloud/aiplatform_v1/services/prediction_service/client.py\", line 2159, in generate_content\n    response = rpc(\n  File \"/home/rafael/.local/lib/python3.9/site-packages/google/api_core/gapic_v1/method.py\", line 131, in __call__\n    return wrapped_func(*args, **kwargs)\n  File \"/home/rafael/.local/lib/python3.9/site-packages/google/api_core/grpc_helpers.py\", line 78, in error_remapped_callable\n    raise exceptions.from_grpc_error(exc) from exc\ngoogle.api_core.exceptions.NotFound: 404 Publisher Model `projects/conteudo-autenticare/locations/us-central1/publishers/google/models/gemini-pro-vision` was not found or your project does not have access to it. Please ensure you are using a valid model version. For more information, see: https://cloud.google.com/vertex-ai/generative-ai/docs/learn/model-versions"}}
{"timestamp": "2025-05-16T03:14:53.314528", "level": "ERROR", "logger": "app.utils.verificaImagemVideo", "message": "Erro ao analisar imagem: 404 Publisher Model `projects/conteudo-autenticare/locations/us-central1/publishers/google/models/gemini-pro-vision` was not found or your project does not have access to it. Please ensure you are using a valid model version. For more information, see: https://cloud.google.com/vertex-ai/generative-ai/docs/learn/model-versions", "exception": {"type": "NotFound", "message": "404 Publisher Model `projects/conteudo-autenticare/locations/us-central1/publishers/google/models/gemini-pro-vision` was not found or your project does not have access to it. Please ensure you are using a valid model version. For more information, see: https://cloud.google.com/vertex-ai/generative-ai/docs/learn/model-versions", "traceback": "Traceback (most recent call last):\n  File \"/home/rafael/.local/lib/python3.9/site-packages/google/api_core/grpc_helpers.py\", line 76, in error_remapped_callable\n    return callable_(*args, **kwargs)\n  File \"/home/rafael/.local/lib/python3.9/site-packages/grpc/_channel.py\", line 1181, in __call__\n    return _end_unary_response_blocking(state, call, False, None)\n  File \"/home/rafael/.local/lib/python3.9/site-packages/grpc/_channel.py\", line 1006, in _end_unary_response_blocking\n    raise _InactiveRpcError(state)  # pytype: disable=not-instantiable\ngrpc._channel._InactiveRpcError: <_InactiveRpcError of RPC that terminated with:\n\tstatus = StatusCode.NOT_FOUND\n\tdetails = \"Publisher Model `projects/conteudo-autenticare/locations/us-central1/publishers/google/models/gemini-pro-vision` was not found or your project does not have access to it. Please ensure you are using a valid model version. For more information, see: https://cloud.google.com/vertex-ai/generative-ai/docs/learn/model-versions\"\n\tdebug_error_string = \"UNKNOWN:Error received from peer ipv4:172.217.28.138:443 {grpc_status:5, grpc_message:\"Publisher Model `projects/conteudo-autenticare/locations/us-central1/publishers/google/models/gemini-pro-vision` was not found or your project does not have access to it. Please ensure you are using a valid model version. For more information, see: https://cloud.google.com/vertex-ai/generative-ai/docs/learn/model-versions\"}\"\n>\n\nThe above exception was the direct cause of the following exception:\n\nTraceback (most recent call last):\n  File \"/home/rafael/Desktop/projetos/yduqs_back/app/utils/verificaImagemVideo.py\", line 83, in analisar_imagem\n    response = model.generate_content([prompt, image])\n  File \"/home/rafael/.local/lib/python3.9/site-packages/vertexai/generative_models/_generative_models.py\", line 654, in generate_content\n    return self._generate_content(\n  File \"/home/rafael/.local/lib/python3.9/site-packages/vertexai/generative_models/_generative_models.py\", line 779, in _generate_content\n    gapic_response = self._prediction_client.generate_content(request=request)\n  File \"/home/rafael/.local/lib/python3.9/site-packages/google/cloud/aiplatform_v1/services/prediction_service/client.py\", line 2159, in generate_content\n    response = rpc(\n  File \"/home/rafael/.local/lib/python3.9/site-packages/google/api_core/gapic_v1/method.py\", line 131, in __call__\n    return wrapped_func(*args, **kwargs)\n  File \"/home/rafael/.local/lib/python3.9/site-packages/google/api_core/grpc_helpers.py\", line 78, in error_remapped_callable\n    raise exceptions.from_grpc_error(exc) from exc\ngoogle.api_core.exceptions.NotFound: 404 Publisher Model `projects/conteudo-autenticare/locations/us-central1/publishers/google/models/gemini-pro-vision` was not found or your project does not have access to it. Please ensure you are using a valid model version. For more information, see: https://cloud.google.com/vertex-ai/generative-ai/docs/learn/model-versions"}}
{"timestamp": "2025-05-16T03:14:55.416678", "level": "ERROR", "logger": "app.utils.verificaImagemVideo", "message": "Erro ao analisar imagem: 404 Publisher Model `projects/conteudo-autenticare/locations/us-central1/publishers/google/models/gemini-pro-vision` was not found or your project does not have access to it. Please ensure you are using a valid model version. For more information, see: https://cloud.google.com/vertex-ai/generative-ai/docs/learn/model-versions", "exception": {"type": "NotFound", "message": "404 Publisher Model `projects/conteudo-autenticare/locations/us-central1/publishers/google/models/gemini-pro-vision` was not found or your project does not have access to it. Please ensure you are using a valid model version. For more information, see: https://cloud.google.com/vertex-ai/generative-ai/docs/learn/model-versions", "traceback": "Traceback (most recent call last):\n  File \"/home/rafael/.local/lib/python3.9/site-packages/google/api_core/grpc_helpers.py\", line 76, in error_remapped_callable\n    return callable_(*args, **kwargs)\n  File \"/home/rafael/.local/lib/python3.9/site-packages/grpc/_channel.py\", line 1181, in __call__\n    return _end_unary_response_blocking(state, call, False, None)\n  File \"/home/rafael/.local/lib/python3.9/site-packages/grpc/_channel.py\", line 1006, in _end_unary_response_blocking\n    raise _InactiveRpcError(state)  # pytype: disable=not-instantiable\ngrpc._channel._InactiveRpcError: <_InactiveRpcError of RPC that terminated with:\n\tstatus = StatusCode.NOT_FOUND\n\tdetails = \"Publisher Model `projects/conteudo-autenticare/locations/us-central1/publishers/google/models/gemini-pro-vision` was not found or your project does not have access to it. Please ensure you are using a valid model version. For more information, see: https://cloud.google.com/vertex-ai/generative-ai/docs/learn/model-versions\"\n\tdebug_error_string = \"UNKNOWN:Error received from peer ipv4:142.250.78.106:443 {grpc_message:\"Publisher Model `projects/conteudo-autenticare/locations/us-central1/publishers/google/models/gemini-pro-vision` was not found or your project does not have access to it. Please ensure you are using a valid model version. For more information, see: https://cloud.google.com/vertex-ai/generative-ai/docs/learn/model-versions\", grpc_status:5}\"\n>\n\nThe above exception was the direct cause of the following exception:\n\nTraceback (most recent call last):\n  File \"/home/rafael/Desktop/projetos/yduqs_back/app/utils/verificaImagemVideo.py\", line 83, in analisar_imagem\n    response = model.generate_content([prompt, image])\n  File \"/home/rafael/.local/lib/python3.9/site-packages/vertexai/generative_models/_generative_models.py\", line 654, in generate_content\n    return self._generate_content(\n  File \"/home/rafael/.local/lib/python3.9/site-packages/vertexai/generative_models/_generative_models.py\", line 779, in _generate_content\n    gapic_response = self._prediction_client.generate_content(request=request)\n  File \"/home/rafael/.local/lib/python3.9/site-packages/google/cloud/aiplatform_v1/services/prediction_service/client.py\", line 2159, in generate_content\n    response = rpc(\n  File \"/home/rafael/.local/lib/python3.9/site-packages/google/api_core/gapic_v1/method.py\", line 131, in __call__\n    return wrapped_func(*args, **kwargs)\n  File \"/home/rafael/.local/lib/python3.9/site-packages/google/api_core/grpc_helpers.py\", line 78, in error_remapped_callable\n    raise exceptions.from_grpc_error(exc) from exc\ngoogle.api_core.exceptions.NotFound: 404 Publisher Model `projects/conteudo-autenticare/locations/us-central1/publishers/google/models/gemini-pro-vision` was not found or your project does not have access to it. Please ensure you are using a valid model version. For more information, see: https://cloud.google.com/vertex-ai/generative-ai/docs/learn/model-versions"}}
{"timestamp": "2025-05-16T03:18:43.104608", "level": "ERROR", "logger": "app.utils.verificaImagemVideo", "message": "Erro ao analisar imagem: 404 Publisher Model `projects/conteudo-autenticare/locations/us-central1/publishers/google/models/gemini-pro-vision` was not found or your project does not have access to it. Please ensure you are using a valid model version. For more information, see: https://cloud.google.com/vertex-ai/generative-ai/docs/learn/model-versions", "exception": {"type": "NotFound", "message": "404 Publisher Model `projects/conteudo-autenticare/locations/us-central1/publishers/google/models/gemini-pro-vision` was not found or your project does not have access to it. Please ensure you are using a valid model version. For more information, see: https://cloud.google.com/vertex-ai/generative-ai/docs/learn/model-versions", "traceback": "Traceback (most recent call last):\n  File \"/home/rafael/.local/lib/python3.9/site-packages/google/api_core/grpc_helpers.py\", line 76, in error_remapped_callable\n    return callable_(*args, **kwargs)\n  File \"/home/rafael/.local/lib/python3.9/site-packages/grpc/_channel.py\", line 1181, in __call__\n    return _end_unary_response_blocking(state, call, False, None)\n  File \"/home/rafael/.local/lib/python3.9/site-packages/grpc/_channel.py\", line 1006, in _end_unary_response_blocking\n    raise _InactiveRpcError(state)  # pytype: disable=not-instantiable\ngrpc._channel._InactiveRpcError: <_InactiveRpcError of RPC that terminated with:\n\tstatus = StatusCode.NOT_FOUND\n\tdetails = \"Publisher Model `projects/conteudo-autenticare/locations/us-central1/publishers/google/models/gemini-pro-vision` was not found or your project does not have access to it. Please ensure you are using a valid model version. For more information, see: https://cloud.google.com/vertex-ai/generative-ai/docs/learn/model-versions\"\n\tdebug_error_string = \"UNKNOWN:Error received from peer ipv4:172.217.28.202:443 {grpc_status:5, grpc_message:\"Publisher Model `projects/conteudo-autenticare/locations/us-central1/publishers/google/models/gemini-pro-vision` was not found or your project does not have access to it. Please ensure you are using a valid model version. For more information, see: https://cloud.google.com/vertex-ai/generative-ai/docs/learn/model-versions\"}\"\n>\n\nThe above exception was the direct cause of the following exception:\n\nTraceback (most recent call last):\n  File \"/home/rafael/Desktop/projetos/yduqs_back/app/utils/verificaImagemVideo.py\", line 86, in analisar_imagem\n    response = model.generate_content([prompt, image])\n  File \"/home/rafael/.local/lib/python3.9/site-packages/vertexai/generative_models/_generative_models.py\", line 654, in generate_content\n    return self._generate_content(\n  File \"/home/rafael/.local/lib/python3.9/site-packages/vertexai/generative_models/_generative_models.py\", line 779, in _generate_content\n    gapic_response = self._prediction_client.generate_content(request=request)\n  File \"/home/rafael/.local/lib/python3.9/site-packages/google/cloud/aiplatform_v1/services/prediction_service/client.py\", line 2159, in generate_content\n    response = rpc(\n  File \"/home/rafael/.local/lib/python3.9/site-packages/google/api_core/gapic_v1/method.py\", line 131, in __call__\n    return wrapped_func(*args, **kwargs)\n  File \"/home/rafael/.local/lib/python3.9/site-packages/google/api_core/grpc_helpers.py\", line 78, in error_remapped_callable\n    raise exceptions.from_grpc_error(exc) from exc\ngoogle.api_core.exceptions.NotFound: 404 Publisher Model `projects/conteudo-autenticare/locations/us-central1/publishers/google/models/gemini-pro-vision` was not found or your project does not have access to it. Please ensure you are using a valid model version. For more information, see: https://cloud.google.com/vertex-ai/generative-ai/docs/learn/model-versions"}}
{"timestamp": "2025-05-16T03:18:47.260368", "level": "ERROR", "logger": "app.utils.verificaImagemVideo", "message": "Erro ao analisar imagem: 404 Publisher Model `projects/conteudo-autenticare/locations/us-central1/publishers/google/models/gemini-pro-vision` was not found or your project does not have access to it. Please ensure you are using a valid model version. For more information, see: https://cloud.google.com/vertex-ai/generative-ai/docs/learn/model-versions", "exception": {"type": "NotFound", "message": "404 Publisher Model `projects/conteudo-autenticare/locations/us-central1/publishers/google/models/gemini-pro-vision` was not found or your project does not have access to it. Please ensure you are using a valid model version. For more information, see: https://cloud.google.com/vertex-ai/generative-ai/docs/learn/model-versions", "traceback": "Traceback (most recent call last):\n  File \"/home/rafael/.local/lib/python3.9/site-packages/google/api_core/grpc_helpers.py\", line 76, in error_remapped_callable\n    return callable_(*args, **kwargs)\n  File \"/home/rafael/.local/lib/python3.9/site-packages/grpc/_channel.py\", line 1181, in __call__\n    return _end_unary_response_blocking(state, call, False, None)\n  File \"/home/rafael/.local/lib/python3.9/site-packages/grpc/_channel.py\", line 1006, in _end_unary_response_blocking\n    raise _InactiveRpcError(state)  # pytype: disable=not-instantiable\ngrpc._channel._InactiveRpcError: <_InactiveRpcError of RPC that terminated with:\n\tstatus = StatusCode.NOT_FOUND\n\tdetails = \"Publisher Model `projects/conteudo-autenticare/locations/us-central1/publishers/google/models/gemini-pro-vision` was not found or your project does not have access to it. Please ensure you are using a valid model version. For more information, see: https://cloud.google.com/vertex-ai/generative-ai/docs/learn/model-versions\"\n\tdebug_error_string = \"UNKNOWN:Error received from peer ipv4:172.217.30.138:443 {grpc_message:\"Publisher Model `projects/conteudo-autenticare/locations/us-central1/publishers/google/models/gemini-pro-vision` was not found or your project does not have access to it. Please ensure you are using a valid model version. For more information, see: https://cloud.google.com/vertex-ai/generative-ai/docs/learn/model-versions\", grpc_status:5}\"\n>\n\nThe above exception was the direct cause of the following exception:\n\nTraceback (most recent call last):\n  File \"/home/rafael/Desktop/projetos/yduqs_back/app/utils/verificaImagemVideo.py\", line 86, in analisar_imagem\n    response = model.generate_content([prompt, image])\n  File \"/home/rafael/.local/lib/python3.9/site-packages/vertexai/generative_models/_generative_models.py\", line 654, in generate_content\n    return self._generate_content(\n  File \"/home/rafael/.local/lib/python3.9/site-packages/vertexai/generative_models/_generative_models.py\", line 779, in _generate_content\n    gapic_response = self._prediction_client.generate_content(request=request)\n  File \"/home/rafael/.local/lib/python3.9/site-packages/google/cloud/aiplatform_v1/services/prediction_service/client.py\", line 2159, in generate_content\n    response = rpc(\n  File \"/home/rafael/.local/lib/python3.9/site-packages/google/api_core/gapic_v1/method.py\", line 131, in __call__\n    return wrapped_func(*args, **kwargs)\n  File \"/home/rafael/.local/lib/python3.9/site-packages/google/api_core/grpc_helpers.py\", line 78, in error_remapped_callable\n    raise exceptions.from_grpc_error(exc) from exc\ngoogle.api_core.exceptions.NotFound: 404 Publisher Model `projects/conteudo-autenticare/locations/us-central1/publishers/google/models/gemini-pro-vision` was not found or your project does not have access to it. Please ensure you are using a valid model version. For more information, see: https://cloud.google.com/vertex-ai/generative-ai/docs/learn/model-versions"}}
{"timestamp": "2025-05-16T03:20:55.713800", "level": "ERROR", "logger": "app.utils.verificaImagemVideo", "message": "Erro ao analisar imagem: 404 Publisher Model `projects/conteudo-autenticare/locations/us-east1/publishers/google/models/gemini-pro-vision` was not found or your project does not have access to it. Please ensure you are using a valid model version. For more information, see: https://cloud.google.com/vertex-ai/generative-ai/docs/learn/model-versions", "exception": {"type": "NotFound", "message": "404 Publisher Model `projects/conteudo-autenticare/locations/us-east1/publishers/google/models/gemini-pro-vision` was not found or your project does not have access to it. Please ensure you are using a valid model version. For more information, see: https://cloud.google.com/vertex-ai/generative-ai/docs/learn/model-versions", "traceback": "Traceback (most recent call last):\n  File \"/home/rafael/.local/lib/python3.9/site-packages/google/api_core/grpc_helpers.py\", line 76, in error_remapped_callable\n    return callable_(*args, **kwargs)\n  File \"/home/rafael/.local/lib/python3.9/site-packages/grpc/_channel.py\", line 1181, in __call__\n    return _end_unary_response_blocking(state, call, False, None)\n  File \"/home/rafael/.local/lib/python3.9/site-packages/grpc/_channel.py\", line 1006, in _end_unary_response_blocking\n    raise _InactiveRpcError(state)  # pytype: disable=not-instantiable\ngrpc._channel._InactiveRpcError: <_InactiveRpcError of RPC that terminated with:\n\tstatus = StatusCode.NOT_FOUND\n\tdetails = \"Publisher Model `projects/conteudo-autenticare/locations/us-east1/publishers/google/models/gemini-pro-vision` was not found or your project does not have access to it. Please ensure you are using a valid model version. For more information, see: https://cloud.google.com/vertex-ai/generative-ai/docs/learn/model-versions\"\n\tdebug_error_string = \"UNKNOWN:Error received from peer ipv4:172.217.29.106:443 {grpc_status:5, grpc_message:\"Publisher Model `projects/conteudo-autenticare/locations/us-east1/publishers/google/models/gemini-pro-vision` was not found or your project does not have access to it. Please ensure you are using a valid model version. For more information, see: https://cloud.google.com/vertex-ai/generative-ai/docs/learn/model-versions\"}\"\n>\n\nThe above exception was the direct cause of the following exception:\n\nTraceback (most recent call last):\n  File \"/home/rafael/Desktop/projetos/yduqs_back/app/utils/verificaImagemVideo.py\", line 86, in analisar_imagem\n    response = model.generate_content([prompt, image])\n  File \"/home/rafael/.local/lib/python3.9/site-packages/vertexai/generative_models/_generative_models.py\", line 654, in generate_content\n    return self._generate_content(\n  File \"/home/rafael/.local/lib/python3.9/site-packages/vertexai/generative_models/_generative_models.py\", line 779, in _generate_content\n    gapic_response = self._prediction_client.generate_content(request=request)\n  File \"/home/rafael/.local/lib/python3.9/site-packages/google/cloud/aiplatform_v1/services/prediction_service/client.py\", line 2159, in generate_content\n    response = rpc(\n  File \"/home/rafael/.local/lib/python3.9/site-packages/google/api_core/gapic_v1/method.py\", line 131, in __call__\n    return wrapped_func(*args, **kwargs)\n  File \"/home/rafael/.local/lib/python3.9/site-packages/google/api_core/grpc_helpers.py\", line 78, in error_remapped_callable\n    raise exceptions.from_grpc_error(exc) from exc\ngoogle.api_core.exceptions.NotFound: 404 Publisher Model `projects/conteudo-autenticare/locations/us-east1/publishers/google/models/gemini-pro-vision` was not found or your project does not have access to it. Please ensure you are using a valid model version. For more information, see: https://cloud.google.com/vertex-ai/generative-ai/docs/learn/model-versions"}}
{"timestamp": "2025-05-16T03:20:59.040905", "level": "ERROR", "logger": "app.utils.verificaImagemVideo", "message": "Erro ao analisar imagem: 404 Publisher Model `projects/conteudo-autenticare/locations/us-east1/publishers/google/models/gemini-pro-vision` was not found or your project does not have access to it. Please ensure you are using a valid model version. For more information, see: https://cloud.google.com/vertex-ai/generative-ai/docs/learn/model-versions", "exception": {"type": "NotFound", "message": "404 Publisher Model `projects/conteudo-autenticare/locations/us-east1/publishers/google/models/gemini-pro-vision` was not found or your project does not have access to it. Please ensure you are using a valid model version. For more information, see: https://cloud.google.com/vertex-ai/generative-ai/docs/learn/model-versions", "traceback": "Traceback (most recent call last):\n  File \"/home/rafael/.local/lib/python3.9/site-packages/google/api_core/grpc_helpers.py\", line 76, in error_remapped_callable\n    return callable_(*args, **kwargs)\n  File \"/home/rafael/.local/lib/python3.9/site-packages/grpc/_channel.py\", line 1181, in __call__\n    return _end_unary_response_blocking(state, call, False, None)\n  File \"/home/rafael/.local/lib/python3.9/site-packages/grpc/_channel.py\", line 1006, in _end_unary_response_blocking\n    raise _InactiveRpcError(state)  # pytype: disable=not-instantiable\ngrpc._channel._InactiveRpcError: <_InactiveRpcError of RPC that terminated with:\n\tstatus = StatusCode.NOT_FOUND\n\tdetails = \"Publisher Model `projects/conteudo-autenticare/locations/us-east1/publishers/google/models/gemini-pro-vision` was not found or your project does not have access to it. Please ensure you are using a valid model version. For more information, see: https://cloud.google.com/vertex-ai/generative-ai/docs/learn/model-versions\"\n\tdebug_error_string = \"UNKNOWN:Error received from peer ipv4:172.217.172.42:443 {grpc_status:5, grpc_message:\"Publisher Model `projects/conteudo-autenticare/locations/us-east1/publishers/google/models/gemini-pro-vision` was not found or your project does not have access to it. Please ensure you are using a valid model version. For more information, see: https://cloud.google.com/vertex-ai/generative-ai/docs/learn/model-versions\"}\"\n>\n\nThe above exception was the direct cause of the following exception:\n\nTraceback (most recent call last):\n  File \"/home/rafael/Desktop/projetos/yduqs_back/app/utils/verificaImagemVideo.py\", line 86, in analisar_imagem\n    response = model.generate_content([prompt, image])\n  File \"/home/rafael/.local/lib/python3.9/site-packages/vertexai/generative_models/_generative_models.py\", line 654, in generate_content\n    return self._generate_content(\n  File \"/home/rafael/.local/lib/python3.9/site-packages/vertexai/generative_models/_generative_models.py\", line 779, in _generate_content\n    gapic_response = self._prediction_client.generate_content(request=request)\n  File \"/home/rafael/.local/lib/python3.9/site-packages/google/cloud/aiplatform_v1/services/prediction_service/client.py\", line 2159, in generate_content\n    response = rpc(\n  File \"/home/rafael/.local/lib/python3.9/site-packages/google/api_core/gapic_v1/method.py\", line 131, in __call__\n    return wrapped_func(*args, **kwargs)\n  File \"/home/rafael/.local/lib/python3.9/site-packages/google/api_core/grpc_helpers.py\", line 78, in error_remapped_callable\n    raise exceptions.from_grpc_error(exc) from exc\ngoogle.api_core.exceptions.NotFound: 404 Publisher Model `projects/conteudo-autenticare/locations/us-east1/publishers/google/models/gemini-pro-vision` was not found or your project does not have access to it. Please ensure you are using a valid model version. For more information, see: https://cloud.google.com/vertex-ai/generative-ai/docs/learn/model-versions"}}
{"timestamp": "2025-05-16T03:21:01.495752", "level": "ERROR", "logger": "app.utils.verificaImagemVideo", "message": "Erro ao analisar imagem: 404 Publisher Model `projects/conteudo-autenticare/locations/us-east1/publishers/google/models/gemini-pro-vision` was not found or your project does not have access to it. Please ensure you are using a valid model version. For more information, see: https://cloud.google.com/vertex-ai/generative-ai/docs/learn/model-versions", "exception": {"type": "NotFound", "message": "404 Publisher Model `projects/conteudo-autenticare/locations/us-east1/publishers/google/models/gemini-pro-vision` was not found or your project does not have access to it. Please ensure you are using a valid model version. For more information, see: https://cloud.google.com/vertex-ai/generative-ai/docs/learn/model-versions", "traceback": "Traceback (most recent call last):\n  File \"/home/rafael/.local/lib/python3.9/site-packages/google/api_core/grpc_helpers.py\", line 76, in error_remapped_callable\n    return callable_(*args, **kwargs)\n  File \"/home/rafael/.local/lib/python3.9/site-packages/grpc/_channel.py\", line 1181, in __call__\n    return _end_unary_response_blocking(state, call, False, None)\n  File \"/home/rafael/.local/lib/python3.9/site-packages/grpc/_channel.py\", line 1006, in _end_unary_response_blocking\n    raise _InactiveRpcError(state)  # pytype: disable=not-instantiable\ngrpc._channel._InactiveRpcError: <_InactiveRpcError of RPC that terminated with:\n\tstatus = StatusCode.NOT_FOUND\n\tdetails = \"Publisher Model `projects/conteudo-autenticare/locations/us-east1/publishers/google/models/gemini-pro-vision` was not found or your project does not have access to it. Please ensure you are using a valid model version. For more information, see: https://cloud.google.com/vertex-ai/generative-ai/docs/learn/model-versions\"\n\tdebug_error_string = \"UNKNOWN:Error received from peer ipv4:172.217.28.42:443 {grpc_message:\"Publisher Model `projects/conteudo-autenticare/locations/us-east1/publishers/google/models/gemini-pro-vision` was not found or your project does not have access to it. Please ensure you are using a valid model version. For more information, see: https://cloud.google.com/vertex-ai/generative-ai/docs/learn/model-versions\", grpc_status:5}\"\n>\n\nThe above exception was the direct cause of the following exception:\n\nTraceback (most recent call last):\n  File \"/home/rafael/Desktop/projetos/yduqs_back/app/utils/verificaImagemVideo.py\", line 86, in analisar_imagem\n    response = model.generate_content([prompt, image])\n  File \"/home/rafael/.local/lib/python3.9/site-packages/vertexai/generative_models/_generative_models.py\", line 654, in generate_content\n    return self._generate_content(\n  File \"/home/rafael/.local/lib/python3.9/site-packages/vertexai/generative_models/_generative_models.py\", line 779, in _generate_content\n    gapic_response = self._prediction_client.generate_content(request=request)\n  File \"/home/rafael/.local/lib/python3.9/site-packages/google/cloud/aiplatform_v1/services/prediction_service/client.py\", line 2159, in generate_content\n    response = rpc(\n  File \"/home/rafael/.local/lib/python3.9/site-packages/google/api_core/gapic_v1/method.py\", line 131, in __call__\n    return wrapped_func(*args, **kwargs)\n  File \"/home/rafael/.local/lib/python3.9/site-packages/google/api_core/grpc_helpers.py\", line 78, in error_remapped_callable\n    raise exceptions.from_grpc_error(exc) from exc\ngoogle.api_core.exceptions.NotFound: 404 Publisher Model `projects/conteudo-autenticare/locations/us-east1/publishers/google/models/gemini-pro-vision` was not found or your project does not have access to it. Please ensure you are using a valid model version. For more information, see: https://cloud.google.com/vertex-ai/generative-ai/docs/learn/model-versions"}}
{"timestamp": "2025-05-16T03:21:03.711130", "level": "ERROR", "logger": "app.utils.verificaImagemVideo", "message": "Erro ao analisar imagem: 404 Publisher Model `projects/conteudo-autenticare/locations/us-east1/publishers/google/models/gemini-pro-vision` was not found or your project does not have access to it. Please ensure you are using a valid model version. For more information, see: https://cloud.google.com/vertex-ai/generative-ai/docs/learn/model-versions", "exception": {"type": "NotFound", "message": "404 Publisher Model `projects/conteudo-autenticare/locations/us-east1/publishers/google/models/gemini-pro-vision` was not found or your project does not have access to it. Please ensure you are using a valid model version. For more information, see: https://cloud.google.com/vertex-ai/generative-ai/docs/learn/model-versions", "traceback": "Traceback (most recent call last):\n  File \"/home/rafael/.local/lib/python3.9/site-packages/google/api_core/grpc_helpers.py\", line 76, in error_remapped_callable\n    return callable_(*args, **kwargs)\n  File \"/home/rafael/.local/lib/python3.9/site-packages/grpc/_channel.py\", line 1181, in __call__\n    return _end_unary_response_blocking(state, call, False, None)\n  File \"/home/rafael/.local/lib/python3.9/site-packages/grpc/_channel.py\", line 1006, in _end_unary_response_blocking\n    raise _InactiveRpcError(state)  # pytype: disable=not-instantiable\ngrpc._channel._InactiveRpcError: <_InactiveRpcError of RPC that terminated with:\n\tstatus = StatusCode.NOT_FOUND\n\tdetails = \"Publisher Model `projects/conteudo-autenticare/locations/us-east1/publishers/google/models/gemini-pro-vision` was not found or your project does not have access to it. Please ensure you are using a valid model version. For more information, see: https://cloud.google.com/vertex-ai/generative-ai/docs/learn/model-versions\"\n\tdebug_error_string = \"UNKNOWN:Error received from peer ipv4:172.217.162.170:443 {grpc_message:\"Publisher Model `projects/conteudo-autenticare/locations/us-east1/publishers/google/models/gemini-pro-vision` was not found or your project does not have access to it. Please ensure you are using a valid model version. For more information, see: https://cloud.google.com/vertex-ai/generative-ai/docs/learn/model-versions\", grpc_status:5}\"\n>\n\nThe above exception was the direct cause of the following exception:\n\nTraceback (most recent call last):\n  File \"/home/rafael/Desktop/projetos/yduqs_back/app/utils/verificaImagemVideo.py\", line 86, in analisar_imagem\n    response = model.generate_content([prompt, image])\n  File \"/home/rafael/.local/lib/python3.9/site-packages/vertexai/generative_models/_generative_models.py\", line 654, in generate_content\n    return self._generate_content(\n  File \"/home/rafael/.local/lib/python3.9/site-packages/vertexai/generative_models/_generative_models.py\", line 779, in _generate_content\n    gapic_response = self._prediction_client.generate_content(request=request)\n  File \"/home/rafael/.local/lib/python3.9/site-packages/google/cloud/aiplatform_v1/services/prediction_service/client.py\", line 2159, in generate_content\n    response = rpc(\n  File \"/home/rafael/.local/lib/python3.9/site-packages/google/api_core/gapic_v1/method.py\", line 131, in __call__\n    return wrapped_func(*args, **kwargs)\n  File \"/home/rafael/.local/lib/python3.9/site-packages/google/api_core/grpc_helpers.py\", line 78, in error_remapped_callable\n    raise exceptions.from_grpc_error(exc) from exc\ngoogle.api_core.exceptions.NotFound: 404 Publisher Model `projects/conteudo-autenticare/locations/us-east1/publishers/google/models/gemini-pro-vision` was not found or your project does not have access to it. Please ensure you are using a valid model version. For more information, see: https://cloud.google.com/vertex-ai/generative-ai/docs/learn/model-versions"}}
